Workbook

Sheet S-Payment Notice
A4: HROne Co., Ltd.
A6: INVOICE
A7: 付款通知
A9: Attn 发至：NNRoad-Hermetic Solutions
D10: Date: | E10: =TODAY() -> 45855
D11: 日期：
D12: Ref. No.: | E12: 45820.581
A13: Service Month 服务月： | B13: ='S-Payslip'!C4 -> 45820 | D13: 编号：
A15: Items 收款项目 | D15: Amount 金额
D17: RMB
A18: Net Salary (To Individual Bank Account) 实发工资（至员工银行账号） | E18: ='S-Payroll Report'!E11 -> 29914.13
A19: Charge On Behalf 代收代付 | E19: =SUM(D20:D31) -> 21150.58
A20: - Social Insurance (To Social Insurance Accounts) 社保（至社保账户） | D20: =SUM('S-Payroll Report'!H11:J11)+SUM('S-Payroll Report'!P11:U11) -> 10099.63
A21: - Housing Fund (To Housing Fund Accounts) 公积金（至公积金账户） | D21: ='S-Payroll Report'!K11+'S-Payroll Report'!V11 -> 8731.8
A22: - Enterprise Annuity (To Annuity Accounts) 企业年金（至年金账户） | D22: ='S-Payroll Report'!L11+'S-Payroll Report'!W11 -> 0
A23: - Commercial Insurance 商业保险 | D23: ='S-Payroll Report'!Y11 -> 0
A24: - Other Benefits 其他福利 | D24: ='S-Payroll Report'!Z11 -> 0
A25: - Union Fee 工会会费 | D25: ='S-Payroll Report'!M11+'S-Payroll Report'!X11 -> 0
A26: - Employer Liability Insurance 雇主责任险 | D26: ='S-Payroll Report'!AD11 -> 0
A27: - IIT 个税 | D27: ='S-Payroll Report'!N11 -> 1879.35
A28: - Expense 报销款 | D28: ='S-Payroll Report'!F11 -> 439.8
A29: - Subsistence Allowance for Foreigners 外籍生活津贴 | D29: ='S-Payroll Report'!G11 -> 0
A30: - Business Tax for Expense 报销款税额 | D30: ='S-Payroll Report'!AB11 -> 0
A31: - Others 其他 | D31: ='S-Payroll Report'!O11+'S-Payroll Report'!AE11 -> 0
A32: Recurring Service Fee 常规服务费 | E32: ='S-Payroll Report'!AA11 -> 450
A33: Other Fee 其他费用 | E33: =SUM(D34:D35) -> 200
A34: - Other Service Fee 其他服务费 | D34: ='Other Fee'!E14 -> 200
A35: - Other charge on behalf Fee 其他代收代付 | D35: ='Other Fee'!E26 -> 0
A36: Deposit 押金 | E36: ='S-Payroll Report'!AC11 -> 0
A37: Balance 差额 | E37: 0
A38: Delay Fee 滞纳金 | E38: 0
A39: Value Added Tax 增值税 | E39: =ROUND(E32*0.0677,2) -> 30.47
B48: Total 总计 | D48: RMB | E48: =SUM(E16:E47) -> 51745.18
B49: Exchange rate 汇率 | C49: 7.16
D50: or USD | E50: =E48/C49 -> 7226.9804
A51: Note 注：
A53: Prepared By 制单 | B53: Checked By 复核 | D53: Approved By 批准
A55: Siyu | B55: Gina | D55: Ann Rui
A57: If payment is made from overseas and Hong Kong/Macao/Taiwan, please make the transfer to the following account. Please DON'T mention any other comments except SERVICE FEE in bank remark. 如果您是在境外、香港、澳门或者台湾支付的，请汇款至以下账户 | C57: If payment is made from Mainland China in RMB, please make the transfer to the following account 如果您是在中国大陆支付的人民币，请汇款至以下账户
A58: Bank Account: 652 369240 838 Beneficiary: HRONE COMPANY LIMITED SWIFT BIC: HSBCHKHHHKH (For areas other than Hong Kong) Bank: HSBC Hong Kong Bank Address: 1 Queen’s Road Central Hong Kong Bank Code: 004 (For local transactions)
...

Sheet Other Fee
A4: HROne Co., Ltd.
A6: Other Fee
A7: 其他服务费
A10: Items 收款项目 | D10: Amount 金额
D12: RMB
A13: Other Service Fee Tax 其他服务费税
A14: Other Service Fee 其他服务费 | E14: =SUM(D15:D25) -> 200
A15: 报销服务费 | B15: 1笔报销
A16: 签证&户口
A17: 外勤服务
A18: 背景调查
A19: 其他 | B19: 异地大礼包 | D19: 200
A26: Other charge on behalf Fee 其他代收代付 | E26: =SUM(D27:D38) -> 0
A27: 快递费
A28: 签证政府费用
A29: Ukey更新
A30: Payment for XX's social benefit
A31: 深圳人服报销退费
A39: Total 合计 | D39: =SUM(D24:D38) -> 0

Sheet MLC to China
A1: Region: | D1: Mainland China
A2: Payment Month: | D2: ='S-Payslip'!C4 -> 45820
A3: Currency: | D3: RMB
A4: Exchange Rate (to USD): | D4: ='S-Payment Notice'!C49 -> 7.16
A7: No. | B7: EE No. | C7: Name | D7: Total Cost | E7: Gross Salary | H7: Other Payment To EE | L7: Expense Claim | Q7: Statutory Payment | AB7: Other Payment Borne By Employer | AF7: Deposit | AG7: Service Fee | AH7: Business Tax | AI7: Remark
E8: Subtotal | F8: Basic Salary | G8: Salary Adjustment | H8: Subtotal | I8: Foreigner Allowance | J8: Bonus(Preferential Tax) | K8: Other | L8: Subtotal | M8: IIT Free Portion | O8: IIT Not Free Portion | Q8: Subtotal | R8: Pension | S8: Medical | T8: Unemployment | U8: Maternity | V8: Work-Related-Injury | W8: Housing Fund | X8: Disability | Y8: Union Fee | Z8: Employer Liability | AA8: Others | AB8: Subtotal | AC8: Commercial Insurance | AD8: IIT ER&BIT | AE8: Others
M9: CIT Free Portion | N9: 25% CIT Applicable | O9: IIT afford by Employer | P9: IIT afford by Employee | S9: Medical | T9: Unemployment | U9: Maternity | V9: Work-Related-Injury | W9: Housing Fund | X9: Disability | Y9: Union Fee | Z9: Employer Liability | AA9: Others | AB9: Subtotal | AC9: Commercial Insurance | AE9: Others
A10: 1 | B10: ='S-Payslip'!C7 -> CUS1525-0002 | C10: ='S-Payslip'!D7 -> 杨明华 Minghua Yang | D10: =E10+H10+L10+Q10+AB10+AF10+AG10+AH10 -> 50324.58 | E10: =SUM(F10:G10) -> 37337.5 | F10: ='S-Payslip'!E7 -> 37337.5 | G10: 0 | H10: =SUM(I10:K10) -> 562 | I10: 0 | J10: ='S-Payslip'!G7 -> 0 | K10: ='S-Payslip'!F7+'S-Payslip'!J7+'S-Payroll Report'!N8-'S-Payslip'!AA7 -> 562 | L10: =SUM(M10:P10) -> 439.8 | M10: =基本信息!EB2 -> 439.8 | N10: =基本信息!EC2 -> 0 | O10: 0 | P10: =基本信息!DR2 -> 0 | Q10: =SUM(R10:AA10) -> 11504.81 | R10: ='S-Payroll Report'!P8 -> 4675.17 | S10: ='S-Payroll Report'!Q8 -> 1683.3 | T10: ='S-Payroll Report'!R8 -> 349.27 | U10: ='S-Payroll Report'!S8 -> 168.33 | V10: ='S-Payroll Report'!T8 -> 206.84 | W10: ='S-Payroll Report'!V8 -> 4365.9 | X10: ='S-Payroll Report'!U8 -> 56 | Y10: ='S-Payroll Report'!X8 -> 0 | Z10: ='S-Payroll Report'!AD8 -> 0 | AA10: ='S-Payroll Report'!AE8+'S-Payroll Report'!Z8 -> 0 | AB10: =SUM(AC10:AE10) -> 0 | AC10: 0 | AD10: ='S-Payroll Report'!AB8 -> 0 | AE10: 0 | AF10: ='S-Payroll Report'!AC8 -> 0 | AG10: ='S-Payroll Report'!AA8 -> 450 | AH10: ='S-Payroll Report'!AF8 -> 30.47
A12: Sum | D12: =SUM(D10:D11) -> 50324.58 | E12: =SUM(E10:E11) -> 37337.5 | F12: =SUM(F10:F11) -> 37337.5 | G12: =SUM(G10:G11) -> 0 | H12: =SUM(H10:H11) -> 562 | I12: =SUM(I10:I11) -> 0 | J12: =SUM(J10:J11) -> 0 | K12: =SUM(K10:K11) -> 562 | ... AH12: =SUM(AH10:AH11) -> 30.47
A13: Sum in USD | D13: =D12/$D$4 -> 7028.5726 | E13: =E12/$D$4 -> 5214.7346 | H13: =H12/$D$4 -> 78.49162 | L13: =L12/$D$4 -> 61.424581 | Q13: =Q12/$D$4 -> 1606.817 | AB13: =AB12/$D$4 -> 0 | AF13: =AF12/$D$4 -> 0 | AG13: =AG12/$D$4 -> 62.849162 | AH13: =AH12/$D$4 -> 4.2555866

Sheet S-Payroll Report
A1: HROne Payroll Report 工资汇总
A4: Duration 发薪月 | C4: ='S-Payslip'!C4 -> 45820 | E4: Client 客户 | H4: ='S-Payslip'!G4 -> NNRoad-Hermetic Solutions
A6: No. 序号 | B6: Department 部门 | C6: ID No. 工号 | D6: Name 姓名 | E6: Net Income 员工实得 | F6: Expense 报销款 | G6: Subsistence Allowance for Foreigners 外籍生活津贴 | H6: Individual Portion 个人部分 | P6: Employer Portion 雇主部分 | AG6: Total Cost 总成本 | AH6: Remark 备注
H7: Pension 养老 | I7: Medical 医疗 | J7: Unemployment 失业 | K7: Housing Fund 公积金 | L7: Annuity 年金 | M7: Union Fee 工会费 | N7: IIT 个税 | O7: Balance For Charge On Behalf 代缴费用补差 | P7: Pension 养老 | Q7: Medical 医疗 | R7: Unemployment 失业 | S7: Maternity 生育 | T7: Work-Related-Injury 工伤 | U7: Disability 残保金 | V7: Housing Fund 公积金 | W7: Annuity 年金 | X7: Union Fee 工会费 | Y7: Commercial Insurance 商业保险 | Z7: Other Benefits 其他福利 | AA7: Service Fee 服务费 | AB7: Business Tax for Expense 报销款税额 | AC7: Deposit 押金 | AD7: Employer Liability Insurance 雇主责任险 | AE7: Others 其他 | AF7: Value Added Tax 增值税
A8: 1 | C8: =IF('S-Payslip'!C7="","",'S-Payslip'!C7) -> CUS1525-0002 | D8: ='S-Payslip'!D7 -> 杨明华 Minghua Yang | E8: ='S-Payslip'!AE7 -> 29914.13 | F8: ='S-Payslip'!AC7 -> 439.8 | G8: ='S-Payslip'!AD7 -> 0 | H8: ='S-Payslip'!P7 -> 2200.08 | I8: ='S-Payslip'!Q7 -> 673.32 | J8: ='S-Payslip'!R7 -> 87.32 | K8: ='S-Payslip'!S7 -> 4365.9 | L8: ='S-Payslip'!X7 -> 0 | M8: ='S-Payslip'!Y7 -> 0 | N8: ='S-Payslip'!AA7+计算结果!BE2 -> 1879.35 | O8: ='S-Payslip'!AB7 -> 0 | P8: =计算结果!BV2 -> 4675.17 | Q8: =计算结果!BW2 -> 1683.3 | R8: =计算结果!BX2 -> 349.27 | S8: =计算结果!BY2 -> 168.33 | T8: =计算结果!BZ2 -> 206.84 | U8: =计算结果!CA2 -> 56 | V8: =计算结果!CB2+计算结果!CC2 -> 4365.9 | W8: =基本信息!BF2 -> 0 | X8: =ROUND(SUM(E8,G8:O8)*2%,2)*0 -> 0 | Y8: =基本信息!CE2 -> 0 | Z8: =基本信息!EM2+基本信息!EN2+基本信息!EO2 -> 0 | AA8: 450 | AB8: =计算结果!BI2*25% -> 0 | AC8: 0 | AF8: =ROUND(AA8*6.77%,2) -> 30.47 | AG8: =SUM(E8:O8)+SUM(P8:AF8) -> 51545.18 | AI8: =基本信息!H2 -> 深圳 | AJ8: =SUM(H8:K8,O8) -> 7326.62 | AK8: =SUM(P8:U8,V8,Z8) -> 11504.81
A11: Sum 合计 | E11: =SUM(E8:E10) -> 29914.13 | F11: =SUM(F8:F10) -> 439.8 | G11: =SUM(G8:G10) -> 0 | H11: =SUM(H8:H10) -> 2200.08 | I11: =SUM(I8:I10) -> 673.32 | J11: =SUM(J8:J10) -> 87.32 | K11: =SUM(K8:K10) -> 4365.9 | L11: =SUM(L8:L10) -> 0 | ... AG11: =SUM(AG8:AG10) -> 51545.18

Sheet S-Payslip
A1: HROne Pay Slip 工资单
A4: Duration 发薪月 | C4: 45820 | E4: Employer 雇主 | G4: =基本信息!A2 -> NNRoad-Hermetic Solutions
A5: No. 序号 | B5: Department 部门 | C5: ID No. 工号 | D5: Name 姓名 | E5: Plus Item 加项 | N5: Basis for Social Benefits Calculation 社保基数 | O5: Basis for Housing Fund Calculation 公积金基数 | P5: Minus Item 减项 | Z5: Adjustment after Tax/税后调整 | AA5: IIT 个税 | AB5: Balance For Charge On Behalf 代缴费用补差 | AC5: Expense 报销款 | AD5: Subsistence Allowance for Foreigners 外籍生活津贴 | AE5: Net Income 实发
E6: Basic Salary 基本工资 | F6: Normal Bonus 日常奖金 | G6: Annual Bonus/13th Salary 年终奖/13薪 | H6: Allowance/Subsidy 津贴/补贴 | I6: OT Payment 加班费 | J6: Income Employer Afford Tax 公司负税项 | K6: Adjustment before Tax/税前调整 | L6: Stock option incentive/股权激励 | M6: Compensation离职补偿金/赔偿金 | N6: Basis for Social Benefits Calculation 社保基数 | O6: Basis for Housing Fund Calculation 公积金基数 | P6: Pension 缴养老 | Q6: Medical 缴医疗 | R6: Unemployment 缴失业 | S6: Housing Fund 缴公积金 | T6: Deduction for 1st/last Month' Absence 入离职缺勤扣 | U6: Deduction for Personal Affair Leave 扣事假 | V6: Deduction for Absenteeism 扣旷工 | W6: Deduction for Sick Leave 扣病假 | X6: Annuity 缴年金 | Y6: Union Fee 工会费
A7: 1 | C7: =IF(基本信息!B2="","",基本信息!B2) -> CUS1525-0002 | D7: =IF(基本信息!C2&基本信息!D2="","",基本信息!C2&" "&基本信息!D2) -> 杨明华 Minghua Yang | E7: =计算结果!C2+计算结果!D2 -> 37337.5 | F7: =计算结果!E2+计算结果!F2+计算结果!G2 -> 497 | G7: =计算结果!BM2 -> 0 | H7: =SUM(计算结果!O2:V2)+计算结果!BG2 -> 1220.6 | I7: =SUM(计算结果!H2:J2) -> 0 | J7: =计算结果!AZ2 -> 58.5 | K7: =计算结果!W2-计算结果!X2+计算结果!Y2 -> 0 | L7: =计算结果!BQ2 -> 0 | M7: =计算结果!BO2 -> 0 | N7: =基本信息!AF2 -> 27501 | O7: =基本信息!AL2 -> 43659 | P7: =计算结果!Z2 -> 2200.08 | Q7: =计算结果!AA2 -> 673.32 | R7: =计算结果!AB2 -> 87.32 | S7: =计算结果!AC2+计算结果!AD2 -> 4365.9 | T7: =计算结果!K2 -> 0 | U7: =计算结果!L2 -> 0 | V7: =计算结果!M2 -> 0 | W7: =计算结果!N2 -> 0 | X7: =计算结果!AG2 -> 0 | Y7: =计算结果!AH2 -> 0 | Z7: =计算结果!BK2-计算结果!BL2 -> 0 | AA7: =计算结果!AX2+计算结果!BN2+计算结果!BP2+计算结果!BR2 -> 1872.85 | AB7: =计算结果!AE2+计算结果!AF2+计算结果!BG2 -> 0 | AC7: =计算结果!BH2+计算结果!BI2 -> 439.8 | AD7: =计算结果!BJ2 -> 0 | AE7: =计算结果!BU2-AC7-AD7 -> 29914.13
A10: Sum 合计 | E10: =SUM(E7:E9) -> 37337.5 | F10: =SUM(F7:F9) -> 497 | G10: =SUM(G7:G9) -> 0 | H10: =SUM(H7:H9) -> 1220.6 | I10: =SUM(I7:I9) -> 0 | J10: =SUM(J7:J9) -> 58.5 | K10: =SUM(K7:K9) -> 0 | L10: =SUM(L7:L9) -> 0 | M10: =SUM(M7:M9) -> 0 | P10: =SUM(P7:P9) -> 2200.08 | Q10: =SUM(Q7:Q9) -> 673.32 | R10: =SUM(R7:R9) -> 87.32 | S10: =SUM(S7:S9) -> 4365.9 | T10: =SUM(T7:T9) -> 0 | U10: =SUM(U7:U9) -> 0 | V10: =SUM(V7:V9) -> 0 | W10: =SUM(W7:W9) -> 0 | ... AE10: =SUM(AE7:AE9) -> 29914.13

Sheet 基本信息
A1: 客户简称 | B1: 工号 | C1: 姓名 | D1: 英文名 | E1: 性别 | F1: 客户类型 | G1: 工作地 | H1: 社保缴纳地 | I1: 公积金缴纳地 | J1: 用工性质 | K1: 服务起始日 | L1: 合同所属地 | M1: 合同起始日 | N1: 合同终止日 | O1: 离职日期 | P1: 税前/税后 | Q1: 基本工资 | R1: 日薪 | S1: 浮动工资 | T1: 交通津贴 | U1: 通讯津贴 | V1: 其他固定津贴 | W1: 中班津贴基数 | X1: 夜班津贴基数 | Y1: 高温津贴基数 | Z1: 高温作业保健食品费基数 | AA1: 有毒有害保健食品费基数 | AB1: 独生子女出生日期 | AC1: 独生子女津贴基数 | AD1: 固定补 | AE1: 固定扣 | AF1: 养老基数 | AG1: 医疗基数 | AH1: 失业基数 | AI1: 生育基数 | AJ1: 工伤基数 | AK1: 残保金基数 | AL1: 公积金基数 | AM1: 补充公积金基数 | AN1: 个人养老% | AO1: 个人医疗% | AP1: 个人失业% | AQ1: 个人公积金% | AR1: 个人补充公积金%（免税） | AS1: 个人补充公积金%（不免税） | AT1: 个人医疗固定数 | AU1: 公司养老% | AV1: 公司医疗% | AW1: 公司失业% | AX1: 公司生育% | AY1: 公司工伤% | AZ1: 公司残保金% | BA1: 公司公积金% | BB1: 公司补充公积金% | BC1: 公司医疗固定数 | BD1: 公司工伤固定数 | BE1: 公司残保固定数 | BF1: 年金% | BG1: 工会费 | BH1: 商业保险计税不发 | BI1: 公司负税1 | BJ1: 外籍生活津贴（免税） | BK1: 税后扣1 | BL1: 免税收入1 | BM1: 证件类型 | BN1: 证件号码 | BO1: 生日 | BP1: 公积金账号 | BQ1: 银行户名 | BR1: 银行账号 | BS1: 银行 | BT1: 部门 | BU1: 岗位 | BV1: 国籍/民族 | BW1: 国籍代码 | BX1: 工资单 | BY1: 电话/手机 | BZ1: 邮箱 | CA1: 账单邮寄地址 | CB1: 邮编 | CC1: 户口性质 | CD1: 户籍地址 | CE1: 商业保险总费用 | CF1: 商业险级别 | CG1: 配偶/子女险 | CH1: 绿色津贴 | CI1: 体检 | CJ1: 档案管理费 | CK1: 13薪/年终奖信息 | CL1: 13薪月份 | CM1: 备注1 | CN1: 个税缴纳地 | CO1: 累计子女教育 | CP1: 累计继续教育 | CQ1: 累计住房贷款利息 | CR1: 累计住房租金 | CS1: 累计赡养老人 | CT1: 累计婴幼儿照护费用 | CU1: 税延养老保险 | CV1: 其他免税扣除（捐款） | CW1: 日薪出勤天数 | CX1: 月奖 | CY1: 季奖 | CZ1: 其他奖金 | DA1: 加班小时150 | DB1: 加班小时200 | DC1: 加班小时300 | DD1: 当月全勤日 | DE1: 入离职缺勤天数 | DF1: 事假天数 | DG1: 旷工天数 | DH1: 病假天数 | DI1: 扣病假工资 | DJ1: 交通费 | DK1: 通讯费 | DL1: 中班天数 | DM1: 夜班天数 | DN1: 高温天数 | DO1: 一次性高温费 | DP1: 高温作业天数 | DQ1: 有毒有害作业天数 | DR1: 补发 | DS1: 补扣 | DT1: 税前调整 | DU1: 养老补缴 | DV1: 医疗补缴 | DW1: 失业补缴 | DX1: 公积金补缴 | DY1: 免税收入2 | DZ1: 计税不发2 | EA1: 公司负税2 | EB1: 报销款 | EC1: 报销款25% | ED1: 税后补 | EE1: 税后扣2 | EF1: 个税调整 | EG1: 13薪/年终奖 | EH1: 离职补偿金/赔偿金 | EI1: 离职补偿金/赔偿金免税额 | EJ1: 补偿计算年限 | EK1: 股权激励 | EL1: 备注2 | EM1: 公司社保补缴 | EN1: 公司公积金补缴 | EO1: 残保金补缴 | EP1: 发薪所属 | EQ1: 开户行所在地 | ER1: 是否代缴社保 | ES1: 是否代缴公积金 | ET1: 是否代缴个税 | EU1: 客户编号
A2: NNRoad-Hermetic Solutions | B2: CUS1525-0002 | C2: 杨明华 | D2: Minghua Yang | E2: Male | F2: Dispatching | G2: 深圳 | H2: 深圳 | I2: 深圳 | J2: 1 | K2: 2019-12-01 | M2: 2023-10-01 | N2: 2025-09-30 | P2: 税前 | Q2: 37337.5 | AF2: 27501 | AG2: 33666 | AH2: 43659 | AI2: 33666 | AJ2: 51709 | AL2: 43659 | AN2: 0.08 | AO2: 0.02 | AP2: 0.002 | AQ2: 0.1 | AU2: 0.17 | AV2: 0.05 | AW2: 0.008 | AX2: 0.005 | AY2: 0.004 | BA2: 0.1 | BE2: 56 | BM2: 1 | BN2: 340403197908151230 | BO2: 29082 | BQ2: 杨明华 | BR2: 6227007200020223600 | BS2: 中国建设银行股份有限公司深圳分行福田支行 | BV2: 中国 | BW2: 156 | BY2: 13510035528 | BZ2: minghua.yang@139.com | CA2: 深圳市龙华区龙华大道世纪春城四期5#楼402 | CB2: 518131 | CC2: Urban | CD2: 深圳市龙华区龙华大道世纪春城四期5#楼402 | CN2: 深圳人服 | CO2: =IFERROR(VLOOKUP($BN2,专项附加!$D:$Q,10,0),0) -> 24000 | CP2: =IFERROR(VLOOKUP($BN2,专项附加!$D:$Q,11,0),0) -> 0 | CQ2: =IFERROR(VLOOKUP($BN2,专项附加!$D:$Q,12,0),0) -> 6000 | CR2: =IFERROR(VLOOKUP($BN2,专项附加!$D:$Q,13,0),0) -> 0 | CS2: =IFERROR(VLOOKUP($BN2,专项附加!$D:$Q,14,0),0) -> 18000 | CT2: =IFERROR(VLOOKUP($BN2,专项附加!$D:$Q,15,0),0) -> 0 | CZ2: 497 | DJ2: 1220.6 | EA2: 58.5 | EB2: 439.8 | EP2: 深圳人服 | EQ2: 深圳 | ER2: Y | ES2: Y | ET2: Y | EU2: CUS1525

Sheet 专项附加
A1: 工号 | B1: 姓名 | C1: 证件类型 | D1: 证件号码 | E1: 所得期间起 | F1: 所得期间止 | G1: 本期收入 | H1: 本期免税收入 | I1: 基本养老保险费 | J1: 基本医疗保险费 | K1: 失业保险费 | L1: 住房公积金 | M1: 累计子女教育 | N1: 累计继续教育 | O1: 累计住房贷款利息 | P1: 累计住房租金 | Q1: 累计赡养老人 | R1: 累计婴幼儿照护费用 | S1: 企业(职业)年金 | T1: 商业健康保险 | U1: 税延养老保险 | V1: 其他 | W1: 准予扣除的捐赠额 | X1: 税前扣除项目合计 | Y1: 减免税额 | Z1: 减除费用标准 | AA1: 已缴税额 | AB1: 备注
B2: 杨明华 | D2: 340403197908151230 | M2: 24000 | O2: 6000 | Q2: 18000

Sheet 计算结果
A1: 工号 | B1: 姓名 | C1: 基本工资 | D1: 浮动工资 | E1: 月奖 | F1: 季奖 | G1: 其他奖金 | H1: 加班工资150 | I1: 加班工资200 | J1: 加班工资300 | K1: 入离职缺勤扣 | L1: 扣事假 | M1: 扣旷工 | N1: 扣病假 | O1: 交通费 | P1: 通讯费 | Q1: 其他津贴 | R1: 中班费 | S1: 夜班费 | T1: 高温费 | U1: 高温作业费 | V1: 有毒有害作业费 | W1: 补发 | X1: 补扣 | Y1: 税前调整 | Z1: 缴养老 | AA1: 缴医疗 | AB1: 缴失业 | AC1: 缴公积金 | AD1: 缴补充公积金（免税） | AE1: 社保调整 | AF1: 公积金调整 | AG1: 年金 | AH1: 工会费 | AI1: 计税不发 | AJ1: 当月税前收入额 | AK1: 当月基本扣除 | AL1: 累计税前收入-员工 | AM1: 累计个人社保公积金 | AN1: 累计基本扣除 | AO1: 累计子女教育 | AP1: 累计继续教育 | AQ1: 累计住房贷款利息 | AR1: 累计住房租金 | AS1: 累计赡养老人 | AT1: 累计其他税前扣除 | AU1: 累计免税扣除合计(不含社保公积金） | AV1: 累计应税总额 | AW1: 累计个税（个人） | AX1: 当月个税（个人） | AY1: 公司负税项 | AZ1: 当月公司负税合计 | BA1: 累计税后计税收入 | BB1: 累计税前收入 | BC1: 导算当月应发工资 | BD1: 累计个税（公司+个人） | BE1: 当月个税（公司） | BF1: 独生子女费 | BG1: 缴补充公积金（不免税） | BH1: 报销款 | BI1: 报销款25% | BJ1: 外籍生活津贴 | BK1: 税后补 | BL1: 税后扣 | BM1: 13薪/年终奖 | BN1: 13薪/年终奖税 | BO1: 离职补偿金/赔偿金 | BP1: 离职补偿金税/赔偿金税 | BQ1: 股权激励 | BR1: 股权激励税 | BS1: 应发 | BT1: 应扣 | BU1: 实发 | BV1: 公司养老 | BW1: 公司医疗 | BX1: 公司失业 | BY1: 生育 | BZ1: 工伤 | CA1: 残保金 | CB1: 公积金 | CC1: 补充公积金（免税） | CD1: 累计已扣工资税 | CE1: 累计婴幼儿照护费用 | CF1: 工会费 | CG1: 雇主责任险 | CH1: 押金 | CI1: 服务费 | CJ1: 增值税
A2: =IF(基本信息!B2="","",基本信息!B2) -> CUS1525-0002 | B2: =IF(基本信息!C2="","",基本信息!C2) -> 杨明华 | C2: =基本信息!Q2+基本信息!R2*基本信息!CW2 -> 37337.5 | D2: =基本信息!S2 -> 0 | E2: =基本信息!CX2 -> 0 | F2: =基本信息!CY2 -> 0 | G2: =基本信息!CZ2 -> 497 | H2: =ROUND(C2*基本信息!DA2*1.5/(21.75*8),2) -> 0 | I2: =ROUND(C2*基本信息!DB2*2/(21.75*8),2) -> 0 | J2: =ROUND(C2*基本信息!DC2*3/(21.75*8),2) -> 0 | K2: =ROUND(IF(AND(基本信息!DD2=23,基本信息!DE2=12),((C2+D2)*12/21.75+(C2+D2)-(C2+D2)*11/21.75)/2,IF(基本信息!DE2>基本信息!DD2/2,(C2+D2)-(C2+D2)*(基本信息!DD2-基本信息!DE2)/21.75,(C2+D2)*基本信息!DE2/21.75)),2) -> 0 | L2: =MAX(0,ROUND((C2+D2)*基本信息!DF2/21.75,2)) -> 0 | M2: =MAX(0,ROUND((C2+D2)*基本信息!DG2/21.75,2)) -> 0 | N2: =基本信息!DI2 -> 0 | O2: =基本信息!T2+基本信息!DJ2 -> 1220.6 | P2: =基本信息!U2+基本信息!DK2 -> 0 | Q2: =基本信息!V2 -> 0 | R2: =基本信息!W2*基本信息!DL2 -> 0 | S2: =基本信息!X2*基本信息!DM2 -> 0 | T2: =基本信息!Y2*基本信息!DN2+基本信息!DO2 -> 0 | U2: =基本信息!Z2*基本信息!DP2 -> 0 | V2: =基本信息!AA2*基本信息!DQ2 -> 0 | W2: =基本信息!AD2+基本信息!DR2 -> 0 | X2: =基本信息!AE2+基本信息!DS2 -> 0 | Y2: =基本信息!DT2 -> 0 | Z2: =IF(VLOOKUP(基本信息!$H2,各地政策!$A:$X,21,0)="进位",ROUNDUP(基本信息!AF2*基本信息!AN2,VLOOKUP(基本信息!$H2,各地政策!$A:$X,20,0)),IF(VLOOKUP(基本信息!$H2,各地政策!$A:$X,21,0)="四舍五入",ROUND(基本信息!AF2*基本信息!AN2,VLOOKUP(基本信息!$H2,各地政策!$A:$X,20,0)),ROUND(基本信息!AF2*基本信息!AN2-IF(VLOOKUP(基本信息!$H2,各地政策!$A:$X,20,0)=0,0.5,IF(VLOOKUP(基本信息!$H2,各地政策!$A:$X,20,0)=1,0.05,0.005)),VLOOKUP(基本信息!$H2,各地政策!$A:$X,20,0)))) -> 2200.08 | AA2: =IF(VLOOKUP(基本信息!$H2,各地政策!$A:$X,21,0)="进位",ROUNDUP(基本信息!AG2*基本信息!AO2,VLOOKUP(基本信息!$H2,各地政策!$A:$X,20,0)),IF(VLOOKUP(基本信息!$H2,各地政策!$A:$X,21,0)="四舍五入",ROUND(基本信息!AG2*基本信息!AO2,VLOOKUP(基本信息!$H2,各地政策!$A:$X,20,0)),ROUND(基本信息!AG2*基本信息!AO2-IF(VLOOKUP(基本信息!$H2,各地政策!$A:$X,20,0)=0,0.5,IF(VLOOKUP(基本信息!$H2,各地政策!$A:$X,20,0)=1,0.05,0.005)),VLOOKUP(基本信息!$H2,各地政策!$A:$X,20,0))))+基本信息!AT2 -> 673.32 | AB2: =IF(VLOOKUP(基本信息!$H2,各地政策!$A:$X,21,0)="进位",ROUNDUP(基本信息!AH2*基本信息!AP2,VLOOKUP(基本信息!$H2,各地政策!$A:$X,20,0)),IF(VLOOKUP(基本信息!$H2,各地政策!$A:$X,21,0)="四舍五入",ROUND(基本信息!AH2*基本信息!AP2,VLOOKUP(基本信息!$H2,各地政策!$A:$X,20,0)),ROUND(基本信息!AH2*基本信息!AP2-IF(VLOOKUP(基本信息!$H2,各地政策!$A:$X,20,0)=0,0.5,IF(VLOOKUP(基本信息!$H2,各地政策!$A:$X,20,0)=1,0.05,0.005)),VLOOKUP(基本信息!$H2,各地政策!$A:$X,20,0)))) -> 87.32 | AC2: =IF(VLOOKUP(基本信息!$I2,各地政策!$A:$X,24,0)="进位",ROUNDUP(基本信息!AL2*基本信息!AQ2,VLOOKUP(基本信息!$I2,各地政策!$A:$X,23,0)),IF(VLOOKUP(基本信息!$I2,各地政策!$A:$X,24,0)="四舍五入",ROUND(基本信息!AL2*基本信息!AQ2,VLOOKUP(基本信息!$I2,各地政策!$A:$X,23,0)),ROUND(基本信息!AL2*基本信息!AQ2-IF(VLOOKUP(基本信息!$I2,各地政策!$A:$X,23,0)=0,0.5,IF(VLOOKUP(基本信息!$I2,各地政策!$A:$X,23,0)=1,0.05,0.005)),VLOOKUP(基本信息!$I2,各地政策!$A:$X,23,0)))) -> 4365.9 | AD2: =IF(VLOOKUP(基本信息!$I2,各地政策!$A:$X,24,0)="进位",ROUNDUP(基本信息!AM2*基本信息!AR2,VLOOKUP(基本信息!$I2,各地政策!$A:$X,23,0)),IF(VLOOKUP(基本信息!$I2,各地政策!$A:$X,24,0)="四舍五入",ROUND(基本信息!AM2*基本信息!AR2,VLOOKUP(基本信息!$I2,各地政策!$A:$X,23,0)),ROUND(基本信息!AM2*基本信息!AR2-IF(VLOOKUP(基本信息!$I2,各地政策!$A:$X,23,0)=0,0.5,IF(VLOOKUP(基本信息!$I2,各地政策!$A:$X,23,0)=1,0.05,0.005)),VLOOKUP(基本信息!$I2,各地政策!$A:$X,23,0)))) -> 0 | AE2: =基本信息!DU2+基本信息!DV2+基本信息!DW2 -> 0 | AF2: =基本信息!DX2 -> 0 | AG2: =基本信息!BF2 -> 0 | AH2: =基本信息!BG2 -> 0 | AI2: =基本信息!BH2+基本信息!DZ2 -> 0 | AJ2: =IF(基本信息!P2="税前",SUM(C2:J2)+SUM(O2:W2)-SUM(K2:N2)-SUM(X2:X2)+Y2-AG2-AH2+AI2,0) -> 39055.1 | AK2: =IF(基本信息!J2=3,MAX(AJ2*0.2,800),5000) -> 5000 | AL2: =IF(基本信息!P2="税前",SUMIF(YTD!$A$2:$A$2386,$A2,YTD!$BB$2:$BB$2386)+SUMIF(YTD!$A$2:$A$2386,$A2,YTD!$AM$2:$AM$2386)+AJ2,0) -> 240461.98 | AM2: =SUMIF(YTD!$A$2:$A$2386,$A2,YTD!$AM$2:$AM$2386)+SUM(Z2:AF2) -> 44478.12 | AN2: =SUMIF(YTD!$A$2:$A$2386,$A2,YTD!$AN$2:$AN$2386)+计算结果!AK2 -> 30000 | AO2: =基本信息!CO2 -> 24000 | AP2: =基本信息!CP2 -> 0 | AQ2: =基本信息!CQ2 -> 6000 | AR2: =基本信息!CR2 -> 0 | AS2: =基本信息!CS2 -> 18000 | AT2: {=SUMPRODUCT((基本信息!$B$2:$B$2375=$A2)*(基本信息!$CU$2:$CV$2375))+SUMIF(YTD!$A$2:$A$2386,$A2,YTD!$AT$2:$AT$2386)} -> 0 | AU2: =SUM(AN2:AT2,CE2) -> 78000 | AV2: =IF(基本信息!P2="税前",AL2-AM2-AU2,0) -> 117983.86 | AW2: {=IF(基本信息!J2=1,MAX((AV2)*{0.03,0.1,0.2,0.25,0.3,0.35,0.45}-12*{0,210,1410,2660,4410,7160,15160},0),IF(基本信息!J2=4,MAX((AL2-AL2*0.2-AU2)*{0.03,0.1,0.2,0.25,0.3,0.35,0.45}-12*{0,210,1410,2660,4410,7160,15160},0),0))} -> 9278.3859 | AX2: {=MAX(ROUND(IF(基本信息!J2=3,MAX((AJ2-IF(AJ2<4000,800,AJ2*0.2))*10%*{2,3,4}-1000*{0,2,7},0),IF(基本信息!J2=2,MAX((AJ2-SUM(Z2:AG2)-AK2)*{0.03,0.1,0.2,0.25,0.3,0.35,0.45}-{0,210,1410,2660,4410,7160,15160},0),IF(基本信息!P2="税前",AW2-ROUND(SUMIF(YTD!$A$2:$A$2386,$A2,YTD!$CD$2:$CD$2386),2),0))),2),0)} -> 1872.85 | AY2: =基本信息!BI2+基本信息!EA2 -> 58.5 | AZ2: =IF(基本信息!P2="税前",0,SUM(C2:J2)-SUM(K2:N2)+SUM(O2:W2)-X2+Y2+AI2)+AY2 -> 58.5 | BA2: =IF(OR(基本信息!J2=1,基本信息!J2=4),IF(基本信息!P2="税前",AL2-AM2-AW2+AZ2,AZ2+SUMIF(YTD!$A$2:$A$2386,$A2,YTD!$BA$2:$BA$2386)),IF(基本信息!P2="税前",AJ2-SUM(Z2:AG2)-AX2+AZ2,AZ2)) -> 186763.97 | BB2: {=IF(基本信息!J2=3,LOOKUP(AJ2-AX2+AZ2,{0,800,3360,21000,49500},(AJ2-AX2+AZ2-{0,160,0,2000,7000})*{1,5,25,25,25}/{1,4,21,19,17}),IF(基本信息!J2=2,MAX((BA2-AK2-10*{0,21,141,266,441,716,1516})/(1-5%*{0.6,2,4,5,6,7,9})+AK2,BA2),IF(基本信息!J2=4,MAX((BA2-AU2-(AL2*0.2)-120*{0,21,141,266,441,716,1516})/(1-5%*{0.6,2,4,5,6,7,9})+AU2+(AL2*0.2),BA2),MAX((BA2-AU2-120*{0,21,141,266,441,716,1516})/(1-5%*{0.6,2,4,5,6,7,9})+AU2,BA2))))} -> 196048.86 | BC2: =IF(OR(基本信息!J2=1,基本信息!J2=4),BB2-IFERROR(VLOOKUP($A2,YTD!$A:$BB,54,0),0),BB2)+SUM(Z2:AF2) -> 39120.1 | BD2: {=IF(基本信息!J2=4,MAX((BB2-BB2*0.2-AU2)*{0.03,0.1,0.2,0.25,0.3,0.35,0.45}-12*{0,210,1410,2660,4410,7160,15160},0),IF(基本信息!J2=3,MAX((BB2-IF(BB2<4000,800,BB2*0.2))*10%*{2,3,4}-1000*{0,2,7},0),IF(基本信息!J2=2,MAX((BB2-AK2)*{0.03,0.1,0.2,0.25,0.3,0.35,0.45}-{0,210,1410,2660,4410,7160,15160},0),MAX((BB2-AU2)*{0.03,0.1,0.2,0.25,0.3,0.35,0.45}-12*{0,210,1410,2660,4410,7160,15160},0))))} -> 9284.8859 | BE2: =MAX(ROUND(IF(基本信息!J2=1,BD2-AX2-ROUND(SUMIF(YTD!$A$2:$A$2386,$A2,YTD!$CD$2:$CD$2386),2),IF(基本信息!J2=4,BD2-AX2-ROUND(SUMIF(YTD!$A$2:$A$2386,$A2,YTD!$CD$2:$CD$2386),2),BD2-AX2)),2),0) -> 6.5 | BF2: =IF(YEARFRAC(基本信息!AB2,TODAY())*12-1<192,基本信息!AC2,0) -> 0 | BG2: =IF(VLOOKUP(基本信息!$I2,各地政策!$A:$X,24,0)="进位",ROUNDUP(基本信息!AM2*基本信息!AS2,VLOOKUP(基本信息!$I2,各地政策!$A:$X,23,0)),IF(VLOOKUP(基本信息!$I2,各地政策!$A:$X,24,0)="四舍五入",ROUND(基本信息!AM2*基本信息!AS2,VLOOKUP(基本信息!$I2,各地政策!$A:$X,23,0)),ROUND(基本信息!AM2*基本信息!AS2-IF(VLOOKUP(基本信息!$I2,各地政策!$A:$X,23,0)=0,0.5,IF(VLOOKUP(基本信息!$I2,各地政策!$A:$X,23,0)=1,0.05,0.005)),VLOOKUP(基本信息!$I2,各地政策!$A:$X,23,0)))) -> 0 | BH2: =基本信息!EB2 -> 439.8 | BI2: =基本信息!EC2 -> 0 | BJ2: =基本信息!BJ2 -> 0 | BK2: =基本信息!BL2+基本信息!DY2+基本信息!ED2 -> 0 | BL2: =基本信息!BK2+基本信息!EE2 -> 0 | BM2: =基本信息!EG2 -> 0 | BN2: {=IF(基本信息!J2=2,MAX((BM2/6)*{0.03,0.1,0.2,0.25,0.3,0.35,0.45}-{0,210,1410,2660,4410,7160,15160},0)*6,ROUND((BM2)*LOOKUP(-(BM2)/12,-{99999,80,55,35,25,12,3,0,-9}*1000,{9,7,6,5,4,2,0.6,0,0}*5%)-LOOKUP(-(BM2)/12,-{99999,80,55,35,25,12,3,0,-9}*1000,{1516,716,441,266,141,21,0,0}*10),2))} -> 0 | BO2: =基本信息!EH2 -> 0 | BP2: {=IFERROR(ROUND(MAX((基本信息!EH2-基本信息!EI2)*{0.03,0.1,0.2,0.25,0.3,0.35,0.45}-12*{0,210,1410,2660,4410,7160,15160},0),2),0)} -> 0 | BQ2: =基本信息!EK2 -> 0 | BR2: {=ROUND((BQ2)*LOOKUP(-BQ2,-{99999,96,66,42,30,14.4,3.6,0,-9}*10000,{9,7,6,5,4,2,0.6,0,0}*5%)-LOOKUP(-BQ2,-{99999,96,66,42,30,14.4,3.6,0,-9}*10000,{18192,8592,5292,3192,1692,252,0,0}*10),2)} -> 0 | BS2: =SUM(C2:J2)+SUM(O2:W2)+Y2+AY2+BF2+BK2+BM2+BO2+BH2+BJ2+BI2+BQ2 -> 39553.4 | BT2: =IF(基本信息!P2="税前",SUM(K2:N2)+SUM(X2,Z2:AH2)+AX2+BG2+BL2+BN2+BP2+BR2,SUM(K2:N2,X2,BL2,BN2,BP2,BR2)) -> 9199.47 | BU2: =ROUND(BS2-BT2,2) -> 30353.93 | BV2: =IF(VLOOKUP(基本信息!$H2,各地政策!$A:$X,21,0)="进位",ROUNDUP(基本信息!AF2*基本信息!AU2,VLOOKUP(基本信息!$H2,各地政策!$A:$X,20,0)),IF(VLOOKUP(基本信息!$H2,各地政策!$A:$X,21,0)="四舍五入",ROUND(基本信息!AF2*基本信息!AU2,VLOOKUP(基本信息!$H2,各地政策!$A:$X,20,0)),ROUND(基本信息!AF2*基本信息!AU2-IF(VLOOKUP(基本信息!$H2,各地政策!$A:$X,20,0)=0,0.5,IF(VLOOKUP(基本信息!$H2,各地政策!$A:$X,20,0)=1,0.05,0.005)),VLOOKUP(基本信息!$H2,各地政策!$A:$X,20,0)))) -> 4675.17 | BW2: =IF(VLOOKUP(基本信息!$H2,各地政策!$A:$X,21,0)="进位",ROUNDUP(基本信息!AG2*基本信息!AV2,VLOOKUP(基本信息!$H2,各地政策!$A:$X,20,0)),IF(VLOOKUP(基本信息!$H2,各地政策!$A:$X,21,0)="四舍五入",ROUND(基本信息!AG2*基本信息!AV2,VLOOKUP(基本信息!$H2,各地政策!$A:$X,20,0)),ROUND(基本信息!AG2*基本信息!AV2-IF(VLOOKUP(基本信息!$H2,各地政策!$A:$X,20,0)=0,0.5,IF(VLOOKUP(基本信息!$H2,各地政策!$A:$X,20,0)=1,0.05,0.005)),VLOOKUP(基本信息!$H2,各地政策!$A:$X,20,0))))+基本信息!BC2 -> 1683.3 | BX2: =IF(VLOOKUP(基本信息!$H2,各地政策!$A:$X,21,0)="进位",ROUNDUP(基本信息!AH2*基本信息!AW2,VLOOKUP(基本信息!$H2,各地政策!$A:$X,20,0)),IF(VLOOKUP(基本信息!$H2,各地政策!$A:$X,21,0)="四舍五入",ROUND(基本信息!AH2*基本信息!AW2,VLOOKUP(基本信息!$H2,各地政策!$A:$X,20,0)),ROUND(基本信息!AH2*基本信息!AW2-IF(VLOOKUP(基本信息!$H2,各地政策!$A:$X,20,0)=0,0.5,IF(VLOOKUP(基本信息!$H2,各地政策!$A:$X,20,0)=1,0.05,0.005)),VLOOKUP(基本信息!$H2,各地政策!$A:$X,20,0)))) -> 349.27 | BY2: =IF(VLOOKUP(基本信息!$H2,各地政策!$A:$X,21,0)="进位",ROUNDUP(基本信息!AI2*基本信息!AX2,VLOOKUP(基本信息!$H2,各地政策!$A:$X,20,0)),IF(VLOOKUP(基本信息!$H2,各地政策!$A:$X,21,0)="四舍五入",ROUND(基本信息!AI2*基本信息!AX2,VLOOKUP(基本信息!$H2,各地政策!$A:$X,20,0)),ROUND(基本信息!AI2*基本信息!AX2-IF(VLOOKUP(基本信息!$H2,各地政策!$A:$X,20,0)=0,0.5,IF(VLOOKUP(基本信息!$H2,各地政策!$A:$X,20,0)=1,0.05,0.005)),VLOOKUP(基本信息!$H2,各地政策!$A:$X,20,0)))) -> 168.33 | BZ2: =IF(VLOOKUP(基本信息!$H2,各地政策!$A:$X,21,0)="进位",ROUNDUP(基本信息!AJ2*基本信息!AY2,VLOOKUP(基本信息!$H2,各地政策!$A:$X,20,0)),IF(VLOOKUP(基本信息!$H2,各地政策!$A:$X,21,0)="四舍五入",ROUND(基本信息!AJ2*基本信息!AY2,VLOOKUP(基本信息!$H2,各地政策!$A:$X,20,0)),ROUND(基本信息!AJ2*基本信息!AY2-IF(VLOOKUP(基本信息!$H2,各地政策!$A:$X,20,0)=0,0.5,IF(VLOOKUP(基本信息!$H2,各地政策!$A:$X,20,0)=1,0.05,0.005)),VLOOKUP(基本信息!$H2,各地政策!$A:$X,20,0))))+基本信息!BD2 -> 206.84 | CA2: =IF(VLOOKUP(基本信息!$H2,各地政策!$A:$X,21,0)="进位",ROUNDUP(基本信息!AK2*基本信息!AZ2+基本信息!BE2,VLOOKUP(基本信息!$H2,各地政策!$A:$X,20,0)),IF(VLOOKUP(基本信息!$H2,各地政策!$A:$X,21,0)="四舍五入",ROUND(基本信息!AK2*基本信息!AZ2+基本信息!BE2,VLOOKUP(基本信息!$H2,各地政策!$A:$X,20,0)),ROUND(基本信息!AK2*基本信息!AZ2+基本信息!BE2-IF(VLOOKUP(基本信息!$H2,各地政策!$A:$X,20,0)=0,0.5,IF(VLOOKUP(基本信息!$H2,各地政策!$A:$X,20,0)=1,0.05,0.005)),VLOOKUP(基本信息!$H2,各地政策!$A:$X,20,0)))) -> 56 | CB2: =IF(VLOOKUP(基本信息!$I2,各地政策!$A:$X,24,0)="进位",ROUNDUP(基本信息!AL2*(基本信息!BA2),VLOOKUP(基本信息!$I2,各地政策!$A:$X,23,0)),IF(VLOOKUP(基本信息!$I2,各地政策!$A:$X,24,0)="四舍五入",ROUND(基本信息!AL2*(基本信息!BA2),VLOOKUP(基本信息!$I2,各地政策!$A:$X,23,0)),ROUND(基本信息!AL2*(基本信息!BA2)-IF(VLOOKUP(基本信息!$I2,各地政策!$A:$X,23,0)=0,0.5,IF(VLOOKUP(基本信息!$I2,各地政策!$A:$X,23,0)=1,0.05,0.005)),VLOOKUP(基本信息!$I2,各地政策!$A:$X,23,0)))) -> 4365.9 | CC2: =IF(VLOOKUP(基本信息!$I2,各地政策!$A:$X,24,0)="进位",ROUNDUP(基本信息!AM2*(基本信息!BB2),VLOOKUP(基本信息!$I2,各地政策!$A:$X,23,0)),IF(VLOOKUP(基本信息!$I2,各地政策!$A:$X,24,0)="四舍五入",ROUND(基本信息!AM2*(基本信息!BB2),VLOOKUP(基本信息!$I2,各地政策!$A:$X,23,0)),ROUND(基本信息!AM2*(基本信息!BB2)-IF(VLOOKUP(基本信息!$I2,各地政策!$A:$X,23,0)=0,0.5,IF(VLOOKUP(基本信息!$I2,各地政策!$A:$X,23,0)=1,0.05,0.005)),VLOOKUP(基本信息!$I2,各地政策!$A:$X,23,0)))) -> 0 | CD2: =AX2+BE2+IFERROR(VLOOKUP($A2,YTD!$A:$CD,82,0),0) -> 9284.89 | CE2: =基本信息!CT2 -> 0 | CF2: ='S-Payroll Report'!X8 -> 0 | CG2: ='S-Payroll Report'!AD8 -> 0 | CH2: ='S-Payroll Report'!AC8 -> 0 | CI2: ='S-Payroll Report'!AA8 -> 450 | CJ2: ='S-Payroll Report'!AF8 -> 30.47 | CK2: =基本信息!EM2+基本信息!EN2+基本信息!EO2 -> 0
A3: =IF(基本信息!B3="","",基本信息!B3) | B3: =IF(基本信息!C3="","",基本信息!C3) | C3: =基本信息!Q3+基本信息!R3*基本信息!CW3 -> 0 | D3: =基本信息!S3 -> 0 | E3: =基本信息!CX3 -> 0 | F3: =基本信息!CY3 -> 0 | G3: =基本信息!CZ3 -> 0 | H3: =ROUND(C3*基本信息!DA3*1.5/(21.75*8),2) -> 0 | I3: =ROUND(C3*基本信息!DB3*2/(21.75*8),2) -> 0 | J3: =ROUND(C3*基本信息!DC3*3/(21.75*8),2) -> 0 | K3: =ROUND(IF(AND(基本信息!DD3=23,基本信息!DE3=12),((C3+D3)*12/21.75+(C3+D3)-(C3+D3)*11/21.75)/2,IF(基本信息!DE3>基本信息!DD3/2,(C3+D3)-(C3+D3)*(基本信息!DD3-基本信息!DE3)/21.75,(C3+D3)*基本信息!DE3/21.75)),2) -> 0 | L3: =MAX(0,ROUND((C3+D3)*基本信息!DF3/21.75,2)) -> 0 | M3: =MAX(0,ROUND((C3+D3)*基本信息!DG3/21.75,2)) -> 0 | N3: =基本信息!DI3 -> 0 | O3: =基本信息!T3+基本信息!DJ3 -> 0 | P3: =基本信息!U3+基本信息!DK3 -> 0 | Q3: =基本信息!V3 -> 0 | R3: =基本信息!W3*基本信息!DL3 -> 0 | S3: =基本信息!X3*基本信息!DM3 -> 0 | T3: =基本信息!Y3*基本信息!DN3+基本信息!DO3 -> 0 | U3: =基本信息!Z3*基本信息!DP3 -> 0 | V3: =基本信息!AA3*基本信息!DQ3 -> 0 | W3: =基本信息!AD3+基本信息!DR3 -> 0 | X3: =基本信息!AE3+基本信息!DS3 -> 0 | Y3: =基本信息!DT3 -> 0 | Z3: =IF(VLOOKUP(基本信息!$H3,各地政策!$A:$X,21,0)="进位",ROUNDUP(基本信息!AF3*基本信息!AN3,VLOOKUP(基本信息!$H3,各地政策!$A:$X,20,0)),IF(VLOOKUP(基本信息!$H3,各地政策!$A:$X,21,0)="四舍五入",ROUND(基本信息!AF3*基本信息!AN3,VLOOKUP(基本信息!$H3,各地政策!$A:$X,20,0)),ROUND(基本信息!AF3*基本信息!AN3-IF(VLOOKUP(基本信息!$H3,各地政策!$A:$X,20,0)=0,0.5,IF(VLOOKUP(基本信息!$H3,各地政策!$A:$X,20,0)=1,0.05,0.005)),VLOOKUP(基本信息!$H3,各地政策!$A:$X,20,0)))) -> #N/A | AA3: =IF(VLOOKUP(基本信息!$H3,各地政策!$A:$X,21,0)="进位",ROUNDUP(基本信息!AG3*基本信息!AO3,VLOOKUP(基本信息!$H3,各地政策!$A:$X,20,0)),IF(VLOOKUP(基本信息!$H3,各地政策!$A:$X,21,0)="四舍五入",ROUND(基本信息!AG3*基本信息!AO3,VLOOKUP(基本信息!$H3,各地政策!$A:$X,20,0)),ROUND(基本信息!AG3*基本信息!AO3-IF(VLOOKUP(基本信息!$H3,各地政策!$A:$X,20,0)=0,0.5,IF(VLOOKUP(基本信息!$H3,各地政策!$A:$X,20,0)=1,0.05,0.005)),VLOOKUP(基本信息!$H3,各地政策!$A:$X,20,0))))+基本信息!AT3 -> #N/A | AB3: =IF(VLOOKUP(基本信息!$H3,各地政策!$A:$X,21,0)="进位",ROUNDUP(基本信息!AH3*基本信息!AP3,VLOOKUP(基本信息!$H3,各地政策!$A:$X,20,0)),IF(VLOOKUP(基本信息!$H3,各地政策!$A:$X,21,0)="四舍五入",ROUND(基本信息!AH3*基本信息!AP3,VLOOKUP(基本信息!$H3,各地政策!$A:$X,20,0)),ROUND(基本信息!AH3*基本信息!AP3-IF(VLOOKUP(基本信息!$H3,各地政策!$A:$X,20,0)=0,0.5,IF(VLOOKUP(基本信息!$H3,各地政策!$A:$X,20,0)=1,0.05,0.005)),VLOOKUP(基本信息!$H3,各地政策!$A:$X,20,0)))) -> #N/A | AC3: =IF(VLOOKUP(基本信息!$I3,各地政策!$A:$X,24,0)="进位",ROUNDUP(基本信息!AL3*基本信息!AQ3,VLOOKUP(基本信息!$I3,各地政策!$A:$X,23,0)),IF(VLOOKUP(基本信息!$I3,各地政策!$A:$X,24,0)="四舍五入",ROUND(基本信息!AL3*基本信息!AQ3,VLOOKUP(基本信息!$I3,各地政策!$A:$X,23,0)),ROUND(基本信息!AL3*基本信息!AQ3-IF(VLOOKUP(基本信息!$I3,各地政策!$A:$X,23,0)=0,0.5,IF(VLOOKUP(基本信息!$I3,各地政策!$A:$X,23,0)=1,0.05,0.005)),VLOOKUP(基本信息!$I3,各地政策!$A:$X,23,0)))) -> #N/A | AD3: =IF(VLOOKUP(基本信息!$I3,各地政策!$A:$X,24,0)="进位",ROUNDUP(基本信息!AM3*基本信息!AR3,VLOOKUP(基本信息!$I3,各地政策!$A:$X,23,0)),IF(VLOOKUP(基本信息!$I3,各地政策!$A:$X,24,0)="四舍五入",ROUND(基本信息!AM3*基本信息!AR3,VLOOKUP(基本信息!$I3,各地政策!$A:$X,23,0)),ROUND(基本信息!AM3*基本信息!AR3-IF(VLOOKUP(基本信息!$I3,各地政策!$A:$X,23,0)=0,0.5,IF(VLOOKUP(基本信息!$I3,各地政策!$A:$X,23,0)=1,0.05,0.005)),VLOOKUP(基本信息!$I3,各地政策!$A:$X,23,0)))) -> #N/A | AE3: =基本信息!DU3+基本信息!DV3+基本信息!DW3 -> 0 | AF3: =基本信息!DX3 -> 0 | AG3: =基本信息!BF3 -> 0 | AH3: =基本信息!BG3 -> 0 | AI3: =基本信息!BH3+基本信息!DZ3 -> 0 | AJ3: =IF(基本信息!P3="税前",SUM(C3:J3)+SUM(O3:W3)-SUM(K3:N3)-SUM(X3:X3)+Y3-AG3-AH3+AI3,0) -> 0 | AK3: =IF(基本信息!J3=3,MAX(AJ3*0.2,800),5000) -> 5000 | AL3: =IF(基本信息!P3="税前",SUMIF(YTD!$A$2:$A$2386,$A3,YTD!$BB$2:$BB$2386)+SUMIF(YTD!$A$2:$A$2386,$A3,YTD!$AM$2:$AM$2386)+AJ3,0) -> 0 | AM3: =SUMIF(YTD!$A$2:$A$2386,$A3,YTD!$AM$2:$AM$2386)+SUM(Z3:AF3) -> #N/A | AN3: =SUMIF(YTD!$A$2:$A$2386,$A3,YTD!$AN$2:$AN$2386)+计算结果!AK3 -> 5000 | AO3: =基本信息!CO3 -> 0 | AP3: =基本信息!CP3 -> 0 | AQ3: =基本信息!CQ3 -> 0 | AR3: =基本信息!CR3 -> 0 | AS3: =基本信息!CS3 -> 0 | AT3: {=SUMPRODUCT((基本信息!$B$2:$B$2375=$A3)*(基本信息!$CU$2:$CV$2375))+SUMIF(YTD!$A$2:$A$2386,$A3,YTD!$AT$2:$AT$2386)} -> 0 | AU3: =SUM(AN3:AT3,CE3) -> 5000 | AV3: =IF(基本信息!P3="税前",AL3-AM3-AU3,0) -> 0 | AW3: {=IF(基本信息!J3=1,MAX((AV3)*{0.03,0.1,0.2,0.25,0.3,0.35,0.45}-12*{0,210,1410,2660,4410,7160,15160},0),IF(基本信息!J3=4,MAX((AL3-AL3*0.2-AU3)*{0.03,0.1,0.2,0.25,0.3,0.35,0.45}-12*{0,210,1410,2660,4410,7160,15160},0),0))} -> 0 | AX3: {=MAX(ROUND(IF(基本信息!J3=3,MAX((AJ3-IF(AJ3<4000,800,AJ3*0.2))*10%*{2,3,4}-1000*{0,2,7},0),IF(基本信息!J3=2,MAX((AJ3-SUM(Z3:AG3)-AK3)*{0.03,0.1,0.2,0.25,0.3,0.35,0.45}-{0,210,1410,2660,4410,7160,15160},0),IF(基本信息!P3="税前",AW3-ROUND(SUMIF(YTD!$A$2:$A$2386,$A3,YTD!$CD$2:$CD$2386),2),0))),2),0)} -> 0 | AY3: =基本信息!BI3+基本信息!EA3 -> 0 | AZ3: =IF(基本信息!P3="税前",0,SUM(C3:J3)-SUM(K3:N3)+SUM(O3:W3)-X3+Y3+AI3)+AY3 -> 0 | BA3: =IF(OR(基本信息!J3=1,基本信息!J3=4),IF(基本信息!P3="税前",AL3-AM3-AW3+AZ3,AZ3+SUMIF(YTD!$A$2:$A$2386,$A3,YTD!$BA$2:$BA$2386)),IF(基本信息!P3="税前",AJ3-SUM(Z3:AG3)-AX3+AZ3+SUMIF(YTD!$A$2:$A$2386,$A3,YTD!$BA$2:$BA$2386),AZ3)) -> 0 | BB3: {=IF(基本信息!J3=3,LOOKUP(AJ3-AX3+AZ3,{0,800,3360,21000,49500},(AJ3-AX3+AZ3-{0,160,0,2000,7000})*{1,5,25,25,25}/{1,4,21,19,17}),IF(基本信息!J3=2,MAX((BA3-AK3-10*{0,21,141,266,441,716,1516})/(1-5%*{0.6,2,4,5,6,7,9})+AK3,BA3),IF(基本信息!J3=4,MAX((BA3-AU3-(AL3*0.2)-120*{0,21,141,266,441,716,1516})/(1-5%*{0.6,2,4,5,6,7,9})+AU3+(AL3*0.2),BA3),MAX((BA3-AU3-120*{0,21,141,266,441,716,1516})/(1-5%*{0.6,2,4,5,6,7,9})+AU3,BA3))))} -> 0 | BC3: =IF(OR(基本信息!J3=1,基本信息!J3=4),BB3-IFERROR(VLOOKUP($A3,YTD!$A:$BB,54,0),0),BB3)+SUM(Z3:AF3) -> #N/A | BD3: {=IF(基本信息!J3=4,MAX((BB3-BB3*0.2-AU3)*{0.03,0.1,0.2,0.25,0.3,0.35,0.45}-12*{0,210,1410,2660,4410,7160,15160},0),IF(基本信息!J3=3,MAX((BB3-IF(BB3<4000,800,BB3*0.2))*10%*{2,3,4}-1000*{0,2,7},0),IF(基本信息!J3=2,MAX((BB3-AK3)*{0.03,0.1,0.2,0.25,0.3,0.35,0.45}-{0,210,1410,2660,4410,7160,15160},0),MAX((BB3-AU3)*{0.03,0.1,0.2,0.25,0.3,0.35,0.45}-12*{0,210,1410,2660,4410,7160,15160},0))))} -> 0 | BE3: =MAX(ROUND(IF(基本信息!J3=1,BD3-AX3-ROUND(SUMIF(YTD!$A$2:$A$2386,$A3,YTD!$CD$2:$CD$2386),2),IF(基本信息!J3=4,BD3-AX3-ROUND(SUMIF(YTD!$A$2:$A$2386,$A3,YTD!$CD$2:$CD$2386),2),BD3-AX3)),2),0) -> 0 | BF3: =IF(YEARFRAC(基本信息!AB3,TODAY())*12-1<192,基本信息!AC3,0) -> 0 | BG3: =IF(VLOOKUP(基本信息!$I3,各地政策!$A:$X,24,0)="进位",ROUNDUP(基本信息!AM3*基本信息!AS3,VLOOKUP(基本信息!$I3,各地政策!$A:$X,23,0)),IF(VLOOKUP(基本信息!$I3,各地政策!$A:$X,24,0)="四舍五入",ROUND(基本信息!AM3*基本信息!AS3,VLOOKUP(基本信息!$I3,各地政策!$A:$X,23,0)),ROUND(基本信息!AM3*基本信息!AS3-IF(VLOOKUP(基本信息!$I3,各地政策!$A:$X,23,0)=0,0.5,IF(VLOOKUP(基本信息!$I3,各地政策!$A:$X,23,0)=1,0.05,0.005)),VLOOKUP(基本信息!$I3,各地政策!$A:$X,23,0)))) -> #N/A | BH3: =基本信息!EB3 -> 0 | BI3: =基本信息!EC3 -> 0 | BJ3: =基本信息!BJ3 -> 0 | BK3: =基本信息!BL3+基本信息!DY3+基本信息!ED3 -> 0 | BL3: =基本信息!BK3+基本信息!EE3 -> 0 | BM3: =基本信息!EG3 -> 0 | BN3: {=IF(基本信息!J3=2,MAX((BM3/6)*{0.03,0.1,0.2,0.25,0.3,0.35,0.45}-{0,210,1410,2660,4410,7160,15160},0)*6,ROUND((BM3)*LOOKUP(-(BM3)/12,-{99999,80,55,35,25,12,3,0,-9}*1000,{9,7,6,5,4,2,0.6,0,0}*5%)-LOOKUP(-(BM3)/12,-{99999,80,55,35,25,12,3,0,-9}*1000,{1516,716,441,266,141,21,0,0}*10),2))} -> 0 | BO3: =基本信息!EH3 -> 0 | BP3: {=IFERROR(ROUND(MAX((基本信息!EH3-基本信息!EI3)*{0.03,0.1,0.2,0.25,0.3,0.35,0.45}-12*{0,210,1410,2660,4410,7160,15160},0),2),0)} -> 0 | BQ3: =基本信息!EK3 -> 0 | BR3: {=ROUND((BQ3)*LOOKUP(-BQ3,-{99999,96,66,42,30,14.4,3.6,0,-9}*10000,{9,7,6,5,4,2,0.6,0,0}*5%)-LOOKUP(-BQ3,-{99999,96,66,42,30,14.4,3.6,0,-9}*10000,{18192,8592,5292,3192,1692,252,0,0}*10),2)} -> 0 | BS3: =SUM(C3:J3)+SUM(O3:W3)+Y3+AY3+BF3+BK3+BM3+BO3+BH3+BJ3+BI3+BQ3 -> 0 | BT3: =IF(基本信息!P3="税前",SUM(K3:N3)+SUM(X3,Z3:AH3)+AX3+BG3+BL3+BN3+BP3+BR3,SUM(K3:N3,X3,BL3,BN3,BP3,BR3)) -> 0 | BU3: =ROUND(BS3-BT3,2) -> 0 | BV3: =IF(VLOOKUP(基本信息!$H3,各地政策!$A:$X,21,0)="进位",ROUNDUP(基本信息!AF3*基本信息!AU3,VLOOKUP(基本信息!$H3,各地政策!$A:$X,20,0)),IF(VLOOKUP(基本信息!$H3,各地政策!$A:$X,21,0)="四舍五入",ROUND(基本信息!AF3*基本信息!AU3,VLOOKUP(基本信息!$H3,各地政策!$A:$X,20,0)),ROUND(基本信息!AF3*基本信息!AU3-IF(VLOOKUP(基本信息!$H3,各地政策!$A:$X,20,0)=0,0.5,IF(VLOOKUP(基本信息!$H3,各地政策!$A:$X,20,0)=1,0.05,0.005)),VLOOKUP(基本信息!$H3,各地政策!$A:$X,20,0)))) -> #N/A | BW3: =IF(VLOOKUP(基本信息!$H3,各地政策!$A:$X,21,0)="进位",ROUNDUP(基本信息!AG3*基本信息!AV3,VLOOKUP(基本信息!$H3,各地政策!$A:$X,20,0)),IF(VLOOKUP(基本信息!$H3,各地政策!$A:$X,21,0)="四舍五入",ROUND(基本信息!AG3*基本信息!AV3,VLOOKUP(基本信息!$H3,各地政策!$A:$X,20,0)),ROUND(基本信息!AG3*基本信息!AV3-IF(VLOOKUP(基本信息!$H3,各地政策!$A:$X,20,0)=0,0.5,IF(VLOOKUP(基本信息!$H3,各地政策!$A:$X,20,0)=1,0.05,0.005)),VLOOKUP(基本信息!$H3,各地政策!$A:$X,20,0))))+基本信息!BC3 -> #N/A | BX3: =IF(VLOOKUP(基本信息!$H3,各地政策!$A:$X,21,0)="进位",ROUNDUP(基本信息!AH3*基本信息!AW3,VLOOKUP(基本信息!$H3,各地政策!$A:$X,20,0)),IF(VLOOKUP(基本信息!$H3,各地政策!$A:$X,21,0)="四舍五入",ROUND(基本信息!AH3*基本信息!AW3,VLOOKUP(基本信息!$H3,各地政策!$A:$X,20,0)),ROUND(基本信息!AH3*基本信息!AW3-IF(VLOOKUP(基本信息!$H3,各地政策!$A:$X,20,0)=0,0.5,IF(VLOOKUP(基本信息!$H3,各地政策!$A:$X,20,0)=1,0.05,0.005)),VLOOKUP(基本信息!$H3,各地政策!$A:$X,20,0)))) -> #N/A | BY3: =IF(VLOOKUP(基本信息!$H3,各地政策!$A:$X,21,0)="进位",ROUNDUP(基本信息!AI3*基本信息!AX3,VLOOKUP(基本信息!$H3,各地政策!$A:$X,20,0)),IF(VLOOKUP(基本信息!$H3,各地政策!$A:$X,21,0)="四舍五入",ROUND(基本信息!AI3*基本信息!AX3,VLOOKUP(基本信息!$H3,各地政策!$A:$X,20,0)),ROUND(基本信息!AI3*基本信息!AX3-IF(VLOOKUP(基本信息!$H3,各地政策!$A:$X,20,0)=0,0.5,IF(VLOOKUP(基本信息!$H3,各地政策!$A:$X,20,0)=1,0.05,0.005)),VLOOKUP(基本信息!$H3,各地政策!$A:$X,20,0)))) -> #N/A | BZ3: =IF(VLOOKUP(基本信息!$H3,各地政策!$A:$X,21,0)="进位",ROUNDUP(基本信息!AJ3*基本信息!AY3,VLOOKUP(基本信息!$H3,各地政策!$A:$X,20,0)),IF(VLOOKUP(基本信息!$H3,各地政策!$A:$X,21,0)="四舍五入",ROUND(基本信息!AJ3*基本信息!AY3,VLOOKUP(基本信息!$H3,各地政策!$A:$X,20,0)),ROUND(基本信息!AJ3*基本信息!AY3-IF(VLOOKUP(基本信息!$H3,各地政策!$A:$X,20,0)=0,0.5,IF(VLOOKUP(基本信息!$H3,各地政策!$A:$X,20,0)=1,0.05,0.005)),VLOOKUP(基本信息!$H3,各地政策!$A:$X,20,0))))+基本信息!BD3 -> #N/A | CA3: =IF(VLOOKUP(基本信息!$H3,各地政策!$A:$X,21,0)="进位",ROUNDUP(基本信息!AK3*基本信息!AZ3+基本信息!BE3,VLOOKUP(基本信息!$H3,各地政策!$A:$X,20,0)),IF(VLOOKUP(基本信息!$H3,各地政策!$A:$X,21,0)="四舍五入",ROUND(基本信息!AK3*基本信息!AZ3+基本信息!BE3,VLOOKUP(基本信息!$H3,各地政策!$A:$X,20,0)),ROUND(基本信息!AK3*基本信息!AZ3+基本信息!BE3-IF(VLOOKUP(基本信息!$H3,各地政策!$A:$X,20,0)=0,0.5,IF(VLOOKUP(基本信息!$H3,各地政策!$A:$X,20,0)=1,0.05,0.005)),VLOOKUP(基本信息!$H3,各地政策!$A:$X,20,0)))) -> #N/A | CB3: =IF(VLOOKUP(基本信息!$I3,各地政策!$A:$X,24,0)="进位",ROUNDUP(基本信息!AL3*(基本信息!BA3),VLOOKUP(基本信息!$I3,各地政策!$A:$X,23,0)),IF(VLOOKUP(基本信息!$I3,各地政策!$A:$X,24,0)="四舍五入",ROUND(基本信息!AL3*(基本信息!BA3),VLOOKUP(基本信息!$I3,各地政策!$A:$X,23,0)),ROUND(基本信息!AL3*(基本信息!BA3)-IF(VLOOKUP(基本信息!$I3,各地政策!$A:$X,23,0)=0,0.5,IF(VLOOKUP(基本信息!$I3,各地政策!$A:$X,23,0)=1,0.05,0.005)),VLOOKUP(基本信息!$I3,各地政策!$A:$X,23,0)))) -> #N/A | CC3: =IF(VLOOKUP(基本信息!$I3,各地政策!$A:$X,24,0)="进位",ROUNDUP(基本信息!AM3*(基本信息!BB3),VLOOKUP(基本信息!$I3,各地政策!$A:$X,23,0)),IF(VLOOKUP(基本信息!$I3,各地政策!$A:$X,24,0)="四舍五入",ROUND(基本信息!AM3*(基本信息!BB3),VLOOKUP(基本信息!$I3,各地政策!$A:$X,23,0)),ROUND(基本信息!AM3*(基本信息!BB3)-IF(VLOOKUP(基本信息!$I3,各地政策!$A:$X,23,0)=0,0.5,IF(VLOOKUP(基本信息!$I3,各地政策!$A:$X,23,0)=1,0.05,0.005)),VLOOKUP(基本信息!$I3,各地政策!$A:$X,23,0)))) -> #N/A | CD3: =AX3+BE3+IFERROR(VLOOKUP($A3,YTD!$A:$CD,82,0),0) -> 0 | CE3: =基本信息!CT3 -> 0 | CF3: ='S-Payroll Report'!X9 -> 0 | CG3: ='S-Payroll Report'!AD9 -> 0 | CH3: ='S-Payroll Report'!AC9 -> 0 | CI3: ='S-Payroll Report'!AA9 -> 0 | CJ3: ='S-Payroll Report'!AF9 -> 0 | CK3: =基本信息!EM3+基本信息!EN3+基本信息!EO3 -> 0
A4: =IF(基本信息!B4="","",基本信息!B4) | B4: =IF(基本信息!C4="","",基本信息!C4) | C4: =基本信息!Q4+基本信息!R4*基本信息!CW4 -> 0 | D4: =基本信息!S4 -> 0 | E4: =基本信息!CX4 -> 0 | F4: =基本信息!CY4 -> 0 | G4: =基本信息!CZ4 -> 0 | H4: =ROUND(C4*基本信息!DA4*1.5/(21.75*8),2) -> 0 | I4: =ROUND(C4*基本信息!DB4*2/(21.75*8),2) -> 0 | J4: =ROUND(C4*基本信息!DC4*3/(21.75*8),2) -> 0 | K4: =ROUND(IF(AND(基本信息!DD4=23,基本信息!DE4=12),((C4+D4)*12/21.75+(C4+D4)-(C4+D4)*11/21.75)/2,IF(基本信息!DE4>基本信息!DD4/2,(C4+D4)-(C4+D4)*(基本信息!DD4-基本信息!DE4)/21.75,(C4+D4)*基本信息!DE4/21.75)),2) -> 0 | L4: =MAX(0,ROUND((C4+D4)*基本信息!DF4/21.75,2)) -> 0 | M4: =MAX(0,ROUND((C4+D4)*基本信息!DG4/21.75,2)) -> 0 | N4: =基本信息!DI4 -> 0 | O4: =基本信息!T4+基本信息!DJ4 -> 0 | P4: =基本信息!U4+基本信息!DK4 -> 0 | Q4: =基本信息!V4 -> 0 | R4: =基本信息!W4*基本信息!DL4 -> 0 | S4: =基本信息!X4*基本信息!DM4 -> 0 | T4: =基本信息!Y4*基本信息!DN4+基本信息!DO4 -> 0 | U4: =基本信息!Z4*基本信息!DP4 -> 0 | V4: =基本信息!AA4*基本信息!DQ4 -> 0 | W4: =基本信息!AD4+基本信息!DR4 -> 0 | X4: =基本信息!AE4+基本信息!DS4 -> 0 | Y4: =基本信息!DT4 -> 0 | Z4: =IF(VLOOKUP(基本信息!$H4,各地政策!$A:$X,21,0)="进位",ROUNDUP(基本信息!AF4*基本信息!AN4,VLOOKUP(基本信息!$H4,各地政策!$A:$X,20,0)),IF(VLOOKUP(基本信息!$H4,各地政策!$A:$X,21,0)="四舍五入",ROUND(基本信息!AF4*基本信息!AN4,VLOOKUP(基本信息!$H4,各地政策!$A:$X,20,0)),ROUND(基本信息!AF4*基本信息!AN4-IF(VLOOKUP(基本信息!$H4,各地政策!$A:$X,20,0)=0,0.5,IF(VLOOKUP(基本信息!$H4,各地政策!$A:$X,20,0)=1,0.05,0.005)),VLOOKUP(基本信息!$H4,各地政策!$A:$X,20,0)))) -> #N/A | AA4: =IF(VLOOKUP(基本信息!$H4,各地政策!$A:$X,21,0)="进位",ROUNDUP(基本信息!AG4*基本信息!AO4,VLOOKUP(基本信息!$H4,各地政策!$A:$X,20,0)),IF(VLOOKUP(基本信息!$H4,各地政策!$A:$X,21,0)="四舍五入",ROUND(基本信息!AG4*基本信息!AO4,VLOOKUP(基本信息!$H4,各地政策!$A:$X,20,0)),ROUND(基本信息!AG4*基本信息!AO4-IF(VLOOKUP(基本信息!$H4,各地政策!$A:$X,20,0)=0,0.5,IF(VLOOKUP(基本信息!$H4,各地政策!$A:$X,20,0)=1,0.05,0.005)),VLOOKUP(基本信息!$H4,各地政策!$A:$X,20,0))))+基本信息!AT4 -> #N/A | AB4: =IF(VLOOKUP(基本信息!$H4,各地政策!$A:$X,21,0)="进位",ROUNDUP(基本信息!AH4*基本信息!AP4,VLOOKUP(基本信息!$H4,各地政策!$A:$X,20,0)),IF(VLOOKUP(基本信息!$H4,各地政策!$A:$X,21,0)="四舍五入",ROUND(基本信息!AH4*基本信息!AP4,VLOOKUP(基本信息!$H4,各地政策!$A:$X,20,0)),ROUND(基本信息!AH4*基本信息!AP4-IF(VLOOKUP(基本信息!$H4,各地政策!$A:$X,20,0)=0,0.5,IF(VLOOKUP(基本信息!$H4,各地政策!$A:$X,20,0)=1,0.05,0.005)),VLOOKUP(基本信息!$H4,各地政策!$A:$X,20,0)))) -> #N/A | AC4: =IF(VLOOKUP(基本信息!$I4,各地政策!$A:$X,24,0)="进位",ROUNDUP(基本信息!AL4*基本信息!AQ4,VLOOKUP(基本信息!$I4,各地政策!$A:$X,23,0)),IF(VLOOKUP(基本信息!$I4,各地政策!$A:$X,24,0)="四舍五入",ROUND(基本信息!AL4*基本信息!AQ4,VLOOKUP(基本信息!$I4,各地政策!$A:$X,23,0)),ROUND(基本信息!AL4*基本信息!AQ4-IF(VLOOKUP(基本信息!$I4,各地政策!$A:$X,23,0)=0,0.5,IF(VLOOKUP(基本信息!$I4,各地政策!$A:$X,23,0)=1,0.05,0.005)),VLOOKUP(基本信息!$I4,各地政策!$A:$X,23,0)))) -> #N/A | AD4: =IF(VLOOKUP(基本信息!$I4,各地政策!$A:$X,24,0)="进位",ROUNDUP(基本信息!AM4*基本信息!AR4,VLOOKUP(基本信息!$I4,各地政策!$A:$X,23,0)),IF(VLOOKUP(基本信息!$I4,各地政策!$A:$X,24,0)="四舍五入",ROUND(基本信息!AM4*基本信息!AR4,VLOOKUP(基本信息!$I4,各地政策!$A:$X,23,0)),ROUND(基本信息!AM4*基本信息!AR4-IF(VLOOKUP(基本信息!$I4,各地政策!$A:$X,23,0)=0,0.5,IF(VLOOKUP(基本信息!$I4,各地政策!$A:$X,23,0)=1,0.05,0.005)),VLOOKUP(基本信息!$I4,各地政策!$A:$X,23,0)))) -> #N/A | AE4: =基本信息!DU4+基本信息!DV4+基本信息!DW4 -> 0 | AF4: =基本信息!DX4 -> 0 | AG4: =基本信息!BF4 -> 0 | AH4: =基本信息!BG4 -> 0 | AI4: =基本信息!BH4+基本信息!DZ4 -> 0 | AJ4: =IF(基本信息!P4="税前",SUM(C4:J4)+SUM(O4:W4)-SUM(K4:N4)-SUM(X4:X4)+Y4-AG4-AH4+AI4,0) -> 0 | AK4: =IF(基本信息!J4=3,MAX(AJ4*0.2,800),5000) -> 5000 | AL4: =IF(基本信息!P4="税前",SUMIF(YTD!$A$2:$A$2386,$A4,YTD!$BB$2:$BB$2386)+SUMIF(YTD!$A$2:$A$2386,$A4,YTD!$AM$2:$AM$2386)+AJ4,0) -> 0 | AM4: =SUMIF(YTD!$A$2:$A$2386,$A4,YTD!$AM$2:$AM$2386)+SUM(Z4:AF4) -> #N/A | AN4: =SUMIF(YTD!$A$2:$A$2386,$A4,YTD!$AN$2:$AN$2386)+计算结果!AK4 -> 5000 | AO4: =基本信息!CO4 -> 0 | AP4: =基本信息!CP4 -> 0 | AQ4: =基本信息!CQ4 -> 0 | AR4: =基本信息!CR4 -> 0 | AS4: =基本信息!CS4 -> 0 | AT4: {=SUMPRODUCT((基本信息!$B$2:$B$2375=$A4)*(基本信息!$CU$2:$CV$2375))+SUMIF(YTD!$A$2:$A$2386,$A4,YTD!$AT$2:$AT$2386)} -> 0 | AU4: =SUM(AN4:AT4,CE4) -> 5000 | AV4: =IF(基本信息!P4="税前",AL4-AM4-AU4,0) -> 0 | AW4: {=IF(基本信息!J4=1,MAX((AV4)*{0.03,0.1,0.2,0.25,0.3,0.35,0.45}-12*{0,210,1410,2660,4410,7160,15160},0),IF(基本信息!J4=4,MAX((AL4-AL4*0.2-AU4)*{0.03,0.1,0.2,0.25,0.3,0.35,0.45}-12*{0,210,1410,2660,4410,7160,15160},0),0))} -> 0 | AX4: {=MAX(ROUND(IF(基本信息!J4=3,MAX((AJ4-IF(AJ4<4000,800,AJ4*0.2))*10%*{2,3,4}-1000*{0,2,7},0),IF(基本信息!J4=2,MAX((AJ4-SUM(Z4:AG4)-AK4)*{0.03,0.1,0.2,0.25,0.3,0.35,0.45}-{0,210,1410,2660,4410,7160,15160},0),IF(基本信息!P4="税前",AW4-ROUND(SUMIF(YTD!$A$2:$A$2386,$A4,YTD!$CD$2:$CD$2386),2),0))),2),0)} -> 0 | AY4: =基本信息!BI4+基本信息!EA4 -> 0 | AZ4: =IF(基本信息!P4="税前",0,SUM(C4:J4)-SUM(K4:N4)+SUM(O4:W4)-X4+Y4+AI4)+AY4 -> 0 | BA4: =IF(OR(基本信息!J4=1,基本信息!J4=4),IF(基本信息!P4="税前",AL4-AM4-AW4+AZ4,AZ4+SUMIF(YTD!$A$2:$A$2386,$A4,YTD!$BA$2:$BA$2386)),IF(基本信息!P4="税前",AJ4-SUM(Z4:AG4)-AX4+AZ4+SUMIF(YTD!$A$2:$A$2386,$A4,YTD!$BA$2:$BA$2386),AZ4)) -> 0 | BB4: {=IF(基本信息!J4=3,LOOKUP(AJ4-AX4+AZ4,{0,800,3360,21000,49500},(AJ4-AX4+AZ4-{0,160,0,2000,7000})*{1,5,25,25,25}/{1,4,21,19,17}),IF(基本信息!J4=2,MAX((BA4-AK4-10*{0,21,141,266,441,716,1516})/(1-5%*{0.6,2,4,5,6,7,9})+AK4,BA4),IF(基本信息!J4=4,MAX((BA4-AU4-(AL4*0.2)-120*{0,21,141,266,441,716,1516})/(1-5%*{0.6,2,4,5,6,7,9})+AU4+(AL4*0.2),BA4),MAX((BA4-AU4-120*{0,21,141,266,441,716,1516})/(1-5%*{0.6,2,4,5,6,7,9})+AU4,BA4))))} -> 0 | BC4: =IF(OR(基本信息!J4=1,基本信息!J4=4),BB4-IFERROR(VLOOKUP($A4,YTD!$A:$BB,54,0),0),BB4)+SUM(Z4:AF4) -> #N/A | BD4: {=IF(基本信息!J4=4,MAX((BB4-BB4*0.2-AU4)*{0.03,0.1,0.2,0.25,0.3,0.35,0.45}-12*{0,210,1410,2660,4410,7160,15160},0),IF(基本信息!J4=3,MAX((BB4-IF(BB4<4000,800,BB4*0.2))*10%*{2,3,4}-1000*{0,2,7},0),IF(基本信息!J4=2,MAX((BB4-AK4)*{0.03,0.1,0.2,0.25,0.3,0.35,0.45}-{0,210,1410,2660,4410,7160,15160},0),MAX((BB4-AU4)*{0.03,0.1,0.2,0.25,0.3,0.35,0.45}-12*{0,210,1410,2660,4410,7160,15160},0))))} -> 0 | BE4: =MAX(ROUND(IF(基本信息!J4=1,BD4-AX4-ROUND(SUMIF(YTD!$A$2:$A$2386,$A4,YTD!$CD$2:$CD$2386),2),IF(基本信息!J4=4,BD4-AX4-ROUND(SUMIF(YTD!$A$2:$A$2386,$A4,YTD!$CD$2:$CD$2386),2),BD4-AX4)),2),0) -> 0 | BF4: =IF(YEARFRAC(基本信息!AB4,TODAY())*12-1<192,基本信息!AC4,0) -> 0 | BG4: =IF(VLOOKUP(基本信息!$I4,各地政策!$A:$X,24,0)="进位",ROUNDUP(基本信息!AM4*基本信息!AS4,VLOOKUP(基本信息!$I4,各地政策!$A:$X,23,0)),IF(VLOOKUP(基本信息!$I4,各地政策!$A:$X,24,0)="四舍五入",ROUND(基本信息!AM4*基本信息!AS4,VLOOKUP(基本信息!$I4,各地政策!$A:$X,23,0)),ROUND(基本信息!AM4*基本信息!AS4-IF(VLOOKUP(基本信息!$I4,各地政策!$A:$X,23,0)=0,0.5,IF(VLOOKUP(基本信息!$I4,各地政策!$A:$X,23,0)=1,0.05,0.005)),VLOOKUP(基本信息!$I4,各地政策!$A:$X,23,0)))) -> #N/A | BH4: =基本信息!EB4 -> 0 | BI4: =基本信息!EC4 -> 0 | BJ4: =基本信息!BJ4 -> 0 | BK4: =基本信息!BL4+基本信息!DY4+基本信息!ED4 -> 0 | BL4: =基本信息!BK4+基本信息!EE4 -> 0 | BM4: =基本信息!EG4 -> 0 | BN4: {=IF(基本信息!J4=2,MAX((BM4/6)*{0.03,0.1,0.2,0.25,0.3,0.35,0.45}-{0,210,1410,2660,4410,7160,15160},0)*6,ROUND((BM4)*LOOKUP(-(BM4)/12,-{99999,80,55,35,25,12,3,0,-9}*1000,{9,7,6,5,4,2,0.6,0,0}*5%)-LOOKUP(-(BM4)/12,-{99999,80,55,35,25,12,3,0,-9}*1000,{1516,716,441,266,141,21,0,0}*10),2))} -> 0 | BO4: =基本信息!EH4 -> 0 | BP4: {=IFERROR(ROUND(MAX((基本信息!EH4-基本信息!EI4)*{0.03,0.1,0.2,0.25,0.3,0.35,0.45}-12*{0,210,1410,2660,4410,7160,15160},0),2),0)} -> 0 | BQ4: =基本信息!EK4 -> 0 | BR4: {=ROUND((BQ4)*LOOKUP(-BQ4,-{99999,96,66,42,30,14.4,3.6,0,-9}*10000,{9,7,6,5,4,2,0.6,0,0}*5%)-LOOKUP(-BQ4,-{99999,96,66,42,30,14.4,3.6,0,-9}*10000,{18192,8592,5292,3192,1692,252,0,0}*10),2)} -> 0 | BS4: =SUM(C4:J4)+SUM(O4:W4)+Y4+AY4+BF4+BK4+BM4+BO4+BH4+BJ4+BI4+BQ4 -> 0 | BT4: =IF(基本信息!P4="税前",SUM(K4:N4)+SUM(X4,Z4:AH4)+AX4+BG4+BL4+BN4+BP4+BR4,SUM(K4:N4,X4,BL4,BN4,BP4,BR4)) -> 0 | BU4: =ROUND(BS4-BT4,2) -> 0 | BV4: =IF(VLOOKUP(基本信息!$H4,各地政策!$A:$X,21,0)="进位",ROUNDUP(基本信息!AF4*基本信息!AU4,VLOOKUP(基本信息!$H4,各地政策!$A:$X,20,0)),IF(VLOOKUP(基本信息!$H4,各地政策!$A:$X,21,0)="四舍五入",ROUND(基本信息!AF4*基本信息!AU4,VLOOKUP(基本信息!$H4,各地政策!$A:$X,20,0)),ROUND(基本信息!AF4*基本信息!AU4-IF(VLOOKUP(基本信息!$H4,各地政策!$A:$X,20,0)=0,0.5,IF(VLOOKUP(基本信息!$H4,各地政策!$A:$X,20,0)=1,0.05,0.005)),VLOOKUP(基本信息!$H4,各地政策!$A:$X,20,0)))) -> #N/A | BW4: =IF(VLOOKUP(基本信息!$H4,各地政策!$A:$X,21,0)="进位",ROUNDUP(基本信息!AG4*基本信息!AV4,VLOOKUP(基本信息!$H4,各地政策!$A:$X,20,0)),IF(VLOOKUP(基本信息!$H4,各地政策!$A:$X,21,0)="四舍五入",ROUND(基本信息!AG4*基本信息!AV4,VLOOKUP(基本信息!$H4,各地政策!$A:$X,20,0)),ROUND(基本信息!AG4*基本信息!AV4-IF(VLOOKUP(基本信息!$H4,各地政策!$A:$X,20,0)=0,0.5,IF(VLOOKUP(基本信息!$H4,各地政策!$A:$X,20,0)=1,0.05,0.005)),VLOOKUP(基本信息!$H4,各地政策!$A:$X,20,0))))+基本信息!BC4 -> #N/A | BX4: =IF(VLOOKUP(基本信息!$H4,各地政策!$A:$X,21,0)="进位",ROUNDUP(基本信息!AH4*基本信息!AW4,VLOOKUP(基本信息!$H4,各地政策!$A:$X,20,0)),IF(VLOOKUP(基本信息!$H4,各地政策!$A:$X,21,0)="四舍五入",ROUND(基本信息!AH4*基本信息!AW4,VLOOKUP(基本信息!$H4,各地政策!$A:$X,20,0)),ROUND(基本信息!AH4*基本信息!AW4-IF(VLOOKUP(基本信息!$H4,各地政策!$A:$X,20,0)=0,0.5,IF(VLOOKUP(基本信息!$H4,各地政策!$A:$X,20,0)=1,0.05,0.005)),VLOOKUP(基本信息!$H4,各地政策!$A:$X,20,0)))) -> #N/A | BY4: =IF(VLOOKUP(基本信息!$H4,各地政策!$A:$X,21,0)="进位",ROUNDUP(基本信息!AI4*基本信息!AX4,VLOOKUP(基本信息!$H4,各地政策!$A:$X,20,0)),IF(VLOOKUP(基本信息!$H4,各地政策!$A:$X,21,0)="四舍五入",ROUND(基本信息!AI4*基本信息!AX4,VLOOKUP(基本信息!$H4,各地政策!$A:$X,20,0)),ROUND(基本信息!AI4*基本信息!AX4-IF(VLOOKUP(基本信息!$H4,各地政策!$A:$X,20,0)=0,0.5,IF(VLOOKUP(基本信息!$H4,各地政策!$A:$X,20,0)=1,0.05,0.005)),VLOOKUP(基本信息!$H4,各地政策!$A:$X,20,0)))) -> #N/A | BZ4: =IF(VLOOKUP(基本信息!$H4,各地政策!$A:$X,21,0)="进位",ROUNDUP(基本信息!AJ4*基本信息!AY4,VLOOKUP(基本信息!$H4,各地政策!$A:$X,20,0)),IF(VLOOKUP(基本信息!$H4,各地政策!$A:$X,21,0)="四舍五入",ROUND(基本信息!AJ4*基本信息!AY4,VLOOKUP(基本信息!$H4,各地政策!$A:$X,20,0)),ROUND(基本信息!AJ4*基本信息!AY4-IF(VLOOKUP(基本信息!$H4,各地政策!$A:$X,20,0)=0,0.5,IF(VLOOKUP(基本信息!$H4,各地政策!$A:$X,20,0)=1,0.05,0.005)),VLOOKUP(基本信息!$H4,各地政策!$A:$X,20,0))))+基本信息!BD4 -> #N/A | CA4: =IF(VLOOKUP(基本信息!$H4,各地政策!$A:$X,21,0)="进位",ROUNDUP(基本信息!AK4*基本信息!AZ4+基本信息!BE4,VLOOKUP(基本信息!$H4,各地政策!$A:$X,20,0)),IF(VLOOKUP(基本信息!$H4,各地政策!$A:$X,21,0)="四舍五入",ROUND(基本信息!AK4*基本信息!AZ4+基本信息!BE4,VLOOKUP(基本信息!$H4,各地政策!$A:$X,20,0)),ROUND(基本信息!AK4*基本信息!AZ4+基本信息!BE4-IF(VLOOKUP(基本信息!$H4,各地政策!$A:$X,20,0)=0,0.5,IF(VLOOKUP(基本信息!$H4,各地政策!$A:$X,20,0)=1,0.05,0.005)),VLOOKUP(基本信息!$H4,各地政策!$A:$X,20,0)))) -> #N/A | CB4: =IF(VLOOKUP(基本信息!$I4,各地政策!$A:$X,24,0)="进位",ROUNDUP(基本信息!AL4*(基本信息!BA4),VLOOKUP(基本信息!$I4,各地政策!$A:$X,23,0)),IF(VLOOKUP(基本信息!$I4,各地政策!$A:$X,24,0)="四舍五入",ROUND(基本信息!AL4*(基本信息!BA4),VLOOKUP(基本信息!$I4,各地政策!$A:$X,23,0)),ROUND(基本信息!AL4*(基本信息!BA4)-IF(VLOOKUP(基本信息!$I4,各地政策!$A:$X,23,0)=0,0.5,IF(VLOOKUP(基本信息!$I4,各地政策!$A:$X,23,0)=1,0.05,0.005)),VLOOKUP(基本信息!$I4,各地政策!$A:$X,23,0)))) -> #N/A | CC4: =IF(VLOOKUP(基本信息!$I4,各地政策!$A:$X,24,0)="进位",ROUNDUP(基本信息!AM4*(基本信息!BB4),VLOOKUP(基本信息!$I4,各地政策!$A:$X,23,0)),IF(VLOOKUP(基本信息!$I4,各地政策!$A:$X,24,0)="四舍五入",ROUND(基本信息!AM4*(基本信息!BB4),VLOOKUP(基本信息!$I4,各地政策!$A:$X,23,0)),ROUND(基本信息!AM4*(基本信息!BB4)-IF(VLOOKUP(基本信息!$I4,各地政策!$A:$X,23,0)=0,0.5,IF(VLOOKUP(基本信息!$I4,各地政策!$A:$X,23,0)=1,0.05,0.005)),VLOOKUP(基本信息!$I4,各地政策!$A:$X,23,0)))) -> #N/A | CD4: =AX4+BE4+IFERROR(VLOOKUP($A4,YTD!$A:$CD,82,0),0) -> 0 | CE4: =基本信息!CT4 -> 0 | CF4: ='S-Payroll Report'!X10 -> 0 | CG4: ='S-Payroll Report'!AD10 -> 0 | CH4: ='S-Payroll Report'!AC10 -> 0 | CI4: ='S-Payroll Report'!AA10 -> 0 | CJ4: ='S-Payroll Report'!AF10 -> 0 | CK4: =基本信息!EM4+基本信息!EN4+基本信息!EO4 -> 0
A5: =IF(基本信息!B5="","",基本信息!B5) | B5: =IF(基本信息!C5="","",基本信息!C5) | C5: =基本信息!Q5+基本信息!R5*基本信息!CW5 -> 0 | D5: =基本信息!S5 -> 0 | E5: =基本信息!CX5 -> 0 | F5: =基本信息!CY5 -> 0 | G5: =基本信息!CZ5 -> 0 | H5: =ROUND(C5*基本信息!DA5*1.5/(21.75*8),2) -> 0 | I5: =ROUND(C5*基本信息!DB5*2/(21.75*8),2) -> 0 | J5: =ROUND(C5*基本信息!DC5*3/(21.75*8),2) -> 0 | K5: =ROUND(IF(AND(基本信息!DD5=23,基本信息!DE5=12),((C5+D5)*12/21.75+(C5+D5)-(C5+D5)*11/21.75)/2,IF(基本信息!DE5>基本信息!DD5/2,(C5+D5)-(C5+D5)*(基本信息!DD5-基本信息!DE5)/21.75,(C5+D5)*基本信息!DE5/21.75)),2) -> 0 | L5: =MAX(0,ROUND((C5+D5)*基本信息!DF5/21.75,2)) -> 0 | M5: =MAX(0,ROUND((C5+D5)*基本信息!DG5/21.75,2)) -> 0 | N5: =基本信息!DI5 -> 0 | O5: =基本信息!T5+基本信息!DJ5 -> 0 | P5: =基本信息!U5+基本信息!DK5 -> 0 | Q5: =基本信息!V5 -> 0 | R5: =基本信息!W5*基本信息!DL5 -> 0 | S5: =基本信息!X5*基本信息!DM5 -> 0 | T5: =基本信息!Y5*基本信息!DN5+基本信息!DO5 -> 0 | U5: =基本信息!Z5*基本信息!DP5 -> 0 | V5: =基本信息!AA5*基本信息!DQ5 -> 0 | W5: =基本信息!AD5+基本信息!DR5 -> 0 | X5: =基本信息!AE5+基本信息!DS5 -> 0 | Y5: =基本信息!DT5 -> 0 | Z5: =IF(VLOOKUP(基本信息!$H5,各地政策!$A:$X,21,0)="进位",ROUNDUP(基本信息!AF5*基本信息!AN5,VLOOKUP(基本信息!$H5,各地政策!$A:$X,20,0)),IF(VLOOKUP(基本信息!$H5,各地政策!$A:$X,21,0)="四舍五入",ROUND(基本信息!AF5*基本信息!AN5,VLOOKUP(基本信息!$H5,各地政策!$A:$X,20,0)),ROUND(基本信息!AF5*基本信息!AN5-IF(VLOOKUP(基本信息!$H5,各地政策!$A:$X,20,0)=0,0.5,IF(VLOOKUP(基本信息!$H5,各地政策!$A:$X,20,0)=1,0.05,0.005)),VLOOKUP(基本信息!$H5,各地政策!$A:$X,20,0)))) -> #N/A | AA5: =IF(VLOOKUP(基本信息!$H5,各地政策!$A:$X,21,0)="进位",ROUNDUP(基本信息!AG5*基本信息!AO5,VLOOKUP(基本信息!$H5,各地政策!$A:$X,20,0)),IF(VLOOKUP(基本信息!$H5,各地政策!$A:$X,21,0)="四舍五入",ROUND(基本信息!AG5*基本信息!AO5,VLOOKUP(基本信息!$H5,各地政策!$A:$X,20,0)),ROUND(基本信息!AG5*基本信息!AO5-IF(VLOOKUP(基本信息!$H5,各地政策!$A:$X,20,0)=0,0.5,IF(VLOOKUP(基本信息!$H5,各地政策!$A:$X,20,0)=1,0.05,0.005)),VLOOKUP(基本信息!$H5,各地政策!$A:$X,20,0))))+基本信息!AT5 -> #N/A | AB5: =IF(VLOOKUP(基本信息!$H5,各地政策!$A:$X,21,0)="进位",ROUNDUP(基本信息!AH5*基本信息!AP5,VLOOKUP(基本信息!$H5,各地政策!$A:$X,20,0)),IF(VLOOKUP(基本信息!$H5,各地政策!$A:$X,21,0)="四舍五入",ROUND(基本信息!AH5*基本信息!AP5,VLOOKUP(基本信息!$H5,各地政策!$A:$X,20,0)),ROUND(基本信息!AH5*基本信息!AP5-IF(VLOOKUP(基本信息!$H5,各地政策!$A:$X,20,0)=0,0.5,IF(VLOOKUP(基本信息!$H5,各地政策!$A:$X,20,0)=1,0.05,0.005)),VLOOKUP(基本信息!$H5,各地政策!$A:$X,20,0)))) -> #N/A | AC5: =IF(VLOOKUP(基本信息!$I5,各地政策!$A:$X,24,0)="进位",ROUNDUP(基本信息!AL5*基本信息!AQ5,VLOOKUP(基本信息!$I5,各地政策!$A:$X,23,0)),IF(VLOOKUP(基本信息!$I5,各地政策!$A:$X,24,0)="四舍五入",ROUND(基本信息!AL5*基本信息!AQ5,VLOOKUP(基本信息!$I5,各地政策!$A:$X,23,0)),ROUND(基本信息!AL5*基本信息!AQ5-IF(VLOOKUP(基本信息!$I5,各地政策!$A:$X,23,0)=0,0.5,IF(VLOOKUP(基本信息!$I5,各地政策!$A:$X,23,0)=1,0.05,0.005)),VLOOKUP(基本信息!$I5,各地政策!$A:$X,23,0)))) -> #N/A | AD5: =IF(VLOOKUP(基本信息!$I5,各地政策!$A:$X,24,0)="进位",ROUNDUP(基本信息!AM5*基本信息!AR5,VLOOKUP(基本信息!$I5,各地政策!$A:$X,23,0)),IF(VLOOKUP(基本信息!$I5,各地政策!$A:$X,24,0)="四舍五入",ROUND(基本信息!AM5*基本信息!AR5,VLOOKUP(基本信息!$I5,各地政策!$A:$X,23,0)),ROUND(基本信息!AM5*基本信息!AR5-IF(VLOOKUP(基本信息!$I5,各地政策!$A:$X,23,0)=0,0.5,IF(VLOOKUP(基本信息!$I5,各地政策!$A:$X,23,0)=1,0.05,0.005)),VLOOKUP(基本信息!$I5,各地政策!$A:$X,23,0)))) -> #N/A | AE5: =基本信息!DU5+基本信息!DV5+基本信息!DW5 -> 0 | AF5: =基本信息!DX5 -> 0 | AG5: =基本信息!BF5 -> 0 | AH5: =基本信息!BG5 -> 0 | AI5: =基本信息!BH5+基本信息!DZ5 -> 0 | AJ5: =IF(基本信息!P5="税前",SUM(C5:J5)+SUM(O5:W5)-SUM(K5:N5)-SUM(X5:X5)+Y5-AG5-AH5+AI5,0) -> 0 | AK5: =IF(基本信息!J5=3,MAX(AJ5*0.2,800),5000) -> 5000 | AL5: =IF(基本信息!P5="税前",SUMIF(YTD!$A$2:$A$2386,$A5,YTD!$BB$2:$BB$2386)+SUMIF(YTD!$A$2:$A$2386,$A5,YTD!$AM$2:$AM$2386)+AJ5,0) -> 0 | AM5: =SUMIF(YTD!$A$2:$A$2386,$A5,YTD!$AM$2:$AM$2386)+SUM(Z5:AF5) -> #N/A | AN5: =SUMIF(YTD!$A$2:$A$2386,$A5,YTD!$AN$2:$AN$2386)+计算结果!AK5 -> 5000 | AO5: =基本信息!CO5 -> 0 | AP5: =基本信息!CP5 -> 0 | AQ5: =基本信息!CQ5 -> 0 | AR5: =基本信息!CR5 -> 0 | AS5: =基本信息!CS5 -> 0 | AT5: {=SUMPRODUCT((基本信息!$B$2:$B$2375=$A5)*(基本信息!$CU$2:$CV$2375))+SUMIF(YTD!$A$2:$A$2386,$A5,YTD!$AT$2:$AT$2386)} -> 0 | AU5: =SUM(AN5:AT5,CE5) -> 5000 | AV5: =IF(基本信息!P5="税前",AL5-AM5-AU5,0) -> 0 | AW5: {=IF(基本信息!J5=1,MAX((AV5)*{0.03,0.1,0.2,0.25,0.3,0.35,0.45}-12*{0,210,1410,2660,4410,7160,15160},0),IF(基本信息!J5=4,MAX((AL5-AL5*0.2-AU5)*{0.03,0.1,0.2,0.25,0.3,0.35,0.45}-12*{0,210,1410,2660,4410,7160,15160},0),0))} -> 0 | AX5: {=MAX(ROUND(IF(基本信息!J5=3,MAX((AJ5-IF(AJ5<4000,800,AJ5*0.2))*10%*{2,3,4}-1000*{0,2,7},0),IF(基本信息!J5=2,MAX((AJ5-SUM(Z5:AG5)-AK5)*{0.03,0.1,0.2,0.25,0.3,0.35,0.45}-{0,210,1410,2660,4410,7160,15160},0),IF(基本信息!P5="税前",AW5-ROUND(SUMIF(YTD!$A$2:$A$2386,$A5,YTD!$CD$2:$CD$2386),2),0))),2),0)} -> 0 | AY5: =基本信息!BI5+基本信息!EA5 -> 0 | AZ5: =IF(基本信息!P5="税前",0,SUM(C5:J5)-SUM(K5:N5)+SUM(O5:W5)-X5+Y5+AI5)+AY5 -> 0 | BA5: =IF(OR(基本信息!J5=1,基本信息!J5=4),IF(基本信息!P5="税前",AL5-AM5-AW5+AZ5,AZ5+SUMIF(YTD!$A$2:$A$2386,$A5,YTD!$BA$2:$BA$2386)),IF(基本信息!P5="税前",AJ5-SUM(Z5:AG5)-AX5+AZ5+SUMIF(YTD!$A$2:$A$2386,$A5,YTD!$BA$2:$BA$2386),AZ5)) -> 0 | BB5: {=IF(基本信息!J5=3,LOOKUP(AJ5-AX5+AZ5,{0,800,3360,21000,49500},(AJ5-AX5+AZ5-{0,160,0,2000,7000})*{1,5,25,25,25}/{1,4,21,19,17}),IF(基本信息!J5=2,MAX((BA5-AK5-10*{0,21,141,266,441,716,1516})/(1-5%*{0.6,2,4,5,6,7,9})+AK5,BA5),IF(基本信息!J5=4,MAX((BA5-AU5-(AL5*0.2)-120*{0,21,141,266,441,716,1516})/(1-5%*{0.6,2,4,5,6,7,9})+AU5+(AL5*0.2),BA5),MAX((BA5-AU5-120*{0,21,141,266,441,716,1516})/(1-5%*{0.6,2,4,5,6,7,9})+AU5,BA5))))} -> 0 | BC5: =IF(OR(基本信息!J5=1,基本信息!J5=4),BB5-IFERROR(VLOOKUP($A5,YTD!$A:$BB,54,0),0),BB5)+SUM(Z5:AF5) -> #N/A | BD5: {=IF(基本信息!J5=4,MAX((BB5-BB5*0.2-AU5)*{0.03,0.1,0.2,0.25,0.3,0.35,0.45}-12*{0,210,1410,2660,4410,7160,15160},0),IF(基本信息!J5=3,MAX((BB5-IF(BB5<4000,800,BB5*0.2))*10%*{2,3,4}-1000*{0,2,7},0),IF(基本信息!J5=2,MAX((BB5-AK5)*{0.03,0.1,0.2,0.25,0.3,0.35,0.45}-{0,210,1410,2660,4410,7160,15160},0),MAX((BB5-AU5)*{0.03,0.1,0.2,0.25,0.3,0.35,0.45}-12*{0,210,1410,2660,4410,7160,15160},0))))} -> 0 | BE5: =MAX(ROUND(IF(基本信息!J5=1,BD5-AX5-ROUND(SUMIF(YTD!$A$2:$A$2386,$A5,YTD!$CD$2:$CD$2386),2),IF(基本信息!J5=4,BD5-AX5-ROUND(SUMIF(YTD!$A$2:$A$2386,$A5,YTD!$CD$2:$CD$2386),2),BD5-AX5)),2),0) -> 0 | BF5: =IF(YEARFRAC(基本信息!AB5,TODAY())*12-1<192,基本信息!AC5,0) -> 0 | BG5: =IF(VLOOKUP(基本信息!$I5,各地政策!$A:$X,24,0)="进位",ROUNDUP(基本信息!AM5*基本信息!AS5,VLOOKUP(基本信息!$I5,各地政策!$A:$X,23,0)),IF(VLOOKUP(基本信息!$I5,各地政策!$A:$X,24,0)="四舍五入",ROUND(基本信息!AM5*基本信息!AS5,VLOOKUP(基本信息!$I5,各地政策!$A:$X,23,0)),ROUND(基本信息!AM5*基本信息!AS5-IF(VLOOKUP(基本信息!$I5,各地政策!$A:$X,23,0)=0,0.5,IF(VLOOKUP(基本信息!$I5,各地政策!$A:$X,23,0)=1,0.05,0.005)),VLOOKUP(基本信息!$I5,各地政策!$A:$X,23,0)))) -> #N/A | BH5: =基本信息!EB5 -> 0 | BI5: =基本信息!EC5 -> 0 | BJ5: =基本信息!BJ5 -> 0 | BK5: =基本信息!BL5+基本信息!DY5+基本信息!ED5 -> 0 | BL5: =基本信息!BK5+基本信息!EE5 -> 0 | BM5: =基本信息!EG5 -> 0 | BN5: {=IF(基本信息!J5=2,MAX((BM5/6)*{0.03,0.1,0.2,0.25,0.3,0.35,0.45}-{0,210,1410,2660,4410,7160,15160},0)*6,ROUND((BM5)*LOOKUP(-(BM5)/12,-{99999,80,55,35,25,12,3,0,-9}*1000,{9,7,6,5,4,2,0.6,0,0}*5%)-LOOKUP(-(BM5)/12,-{99999,80,55,35,25,12,3,0,-9}*1000,{1516,716,441,266,141,21,0,0}*10),2))} -> 0 | BO5: =基本信息!EH5 -> 0 | BP5: {=IFERROR(ROUND(MAX((基本信息!EH5-基本信息!EI5)*{0.03,0.1,0.2,0.25,0.3,0.35,0.45}-12*{0,210,1410,2660,4410,7160,15160},0),2),0)} -> 0 | BQ5: =基本信息!EK5 -> 0 | BR5: {=ROUND((BQ5)*LOOKUP(-BQ5,-{99999,96,66,42,30,14.4,3.6,0,-9}*10000,{9,7,6,5,4,2,0.6,0,0}*5%)-LOOKUP(-BQ5,-{99999,96,66,42,30,14.4,3.6,0,-9}*10000,{18192,8592,5292,3192,1692,252,0,0}*10),2)} -> 0 | BS5: =SUM(C5:J5)+SUM(O5:W5)+Y5+AY5+BF5+BK5+BM5+BO5+BH5+BJ5+BI5+BQ5 -> 0 | BT5: =IF(基本信息!P5="税前",SUM(K5:N5)+SUM(X5,Z5:AH5)+AX5+BG5+BL5+BN5+BP5+BR5,SUM(K5:N5,X5,BL5,BN5,BP5,BR5)) -> 0 | BU5: =ROUND(BS5-BT5,2) -> 0 | BV5: =IF(VLOOKUP(基本信息!$H5,各地政策!$A:$X,21,0)="进位",ROUNDUP(基本信息!AF5*基本信息!AU5,VLOOKUP(基本信息!$H5,各地政策!$A:$X,20,0)),IF(VLOOKUP(基本信息!$H5,各地政策!$A:$X,21,0)="四舍五入",ROUND(基本信息!AF5*基本信息!AU5,VLOOKUP(基本信息!$H5,各地政策!$A:$X,20,0)),ROUND(基本信息!AF5*基本信息!AU5-IF(VLOOKUP(基本信息!$H5,各地政策!$A:$X,20,0)=0,0.5,IF(VLOOKUP(基本信息!$H5,各地政策!$A:$X,20,0)=1,0.05,0.005)),VLOOKUP(基本信息!$H5,各地政策!$A:$X,20,0)))) -> #N/A | BW5: =IF(VLOOKUP(基本信息!$H5,各地政策!$A:$X,21,0)="进位",ROUNDUP(基本信息!AG5*基本信息!AV5,VLOOKUP(基本信息!$H5,各地政策!$A:$X,20,0)),IF(VLOOKUP(基本信息!$H5,各地政策!$A:$X,21,0)="四舍五入",ROUND(基本信息!AG5*基本信息!AV5,VLOOKUP(基本信息!$H5,各地政策!$A:$X,20,0)),ROUND(基本信息!AG5*基本信息!AV5-IF(VLOOKUP(基本信息!$H5,各地政策!$A:$X,20,0)=0,0.5,IF(VLOOKUP(基本信息!$H5,各地政策!$A:$X,20,0)=1,0.05,0.005)),VLOOKUP(基本信息!$H5,各地政策!$A:$X,20,0))))+基本信息!BC5 -> #N/A | BX5: =IF(VLOOKUP(基本信息!$H5,各地政策!$A:$X,21,0)="进位",ROUNDUP(基本信息!AH5*基本信息!AW5,VLOOKUP(基本信息!$H5,各地政策!$A:$X,20,0)),IF(VLOOKUP(基本信息!$H5,各地政策!$A:$X,21,0)="四舍五入",ROUND(基本信息!AH5*基本信息!AW5,VLOOKUP(基本信息!$H5,各地政策!$A:$X,20,0)),ROUND(基本信息!AH5*基本信息!AW5-IF(VLOOKUP(基本信息!$H5,各地政策!$A:$X,20,0)=0,0.5,IF(VLOOKUP(基本信息!$H5,各地政策!$A:$X,20,0)=1,0.05,0.005)),VLOOKUP(基本信息!$H5,各地政策!$A:$X,20,0)))) -> #N/A | BY5: =IF(VLOOKUP(基本信息!$H5,各地政策!$A:$X,21,0)="进位",ROUNDUP(基本信息!AI5*基本信息!AX5,VLOOKUP(基本信息!$H5,各地政策!$A:$X,20,0)),IF(VLOOKUP(基本信息!$H5,各地政策!$A:$X,21,0)="四舍五入",ROUND(基本信息!AI5*基本信息!AX5,VLOOKUP(基本信息!$H5,各地政策!$A:$X,20,0)),ROUND(基本信息!AI5*基本信息!AX5-IF(VLOOKUP(基本信息!$H5,各地政策!$A:$X,20,0)=0,0.5,IF(VLOOKUP(基本信息!$H5,各地政策!$A:$X,20,0)=1,0.05,0.005)),VLOOKUP(基本信息!$H5,各地政策!$A:$X,20,0)))) -> #N/A | BZ5: =IF(VLOOKUP(基本信息!$H5,各地政策!$A:$X,21,0)="进位",ROUNDUP(基本信息!AJ5*基本信息!AY5,VLOOKUP(基本信息!$H5,各地政策!$A:$X,20,0)),IF(VLOOKUP(基本信息!$H5,各地政策!$A:$X,21,0)="四舍五入",ROUND(基本信息!AJ5*基本信息!AY5,VLOOKUP(基本信息!$H5,各地政策!$A:$X,20,0)),ROUND(基本信息!AJ5*基本信息!AY5-IF(VLOOKUP(基本信息!$H5,各地政策!$A:$X,20,0)=0,0.5,IF(VLOOKUP(基本信息!$H5,各地政策!$A:$X,20,0)=1,0.05,0.005)),VLOOKUP(基本信息!$H5,各地政策!$A:$X,20,0))))+基本信息!BD5 -> #N/A | CA5: =IF(VLOOKUP(基本信息!$H5,各地政策!$A:$X,21,0)="进位",ROUNDUP(基本信息!AK5*基本信息!AZ5+基本信息!BE5,VLOOKUP(基本信息!$H5,各地政策!$A:$X,20,0)),IF(VLOOKUP(基本信息!$H5,各地政策!$A:$X,21,0)="四舍五入",ROUND(基本信息!AK5*基本信息!AZ5+基本信息!BE5,VLOOKUP(基本信息!$H5,各地政策!$A:$X,20,0)),ROUND(基本信息!AK5*基本信息!AZ5+基本信息!BE5-IF(VLOOKUP(基本信息!$H5,各地政策!$A:$X,20,0)=0,0.5,IF(VLOOKUP(基本信息!$H5,各地政策!$A:$X,20,0)=1,0.05,0.005)),VLOOKUP(基本信息!$H5,各地政策!$A:$X,20,0)))) -> #N/A | CB5: =IF(VLOOKUP(基本信息!$I5,各地政策!$A:$X,24,0)="进位",ROUNDUP(基本信息!AL5*(基本信息!BA5),VLOOKUP(基本信息!$I5,各地政策!$A:$X,23,0)),IF(VLOOKUP(基本信息!$I5,各地政策!$A:$X,24,0)="四舍五入",ROUND(基本信息!AL5*(基本信息!BA5),VLOOKUP(基本信息!$I5,各地政策!$A:$X,23,0)),ROUND(基本信息!AL5*(基本信息!BA5)-IF(VLOOKUP(基本信息!$I5,各地政策!$A:$X,23,0)=0,0.5,IF(VLOOKUP(基本信息!$I5,各地政策!$A:$X,23,0)=1,0.05,0.005)),VLOOKUP(基本信息!$I5,各地政策!$A:$X,23,0)))) -> #N/A | CC5: =IF(VLOOKUP(基本信息!$I5,各地政策!$A:$X,24,0)="进位",ROUNDUP(基本信息!AM5*(基本信息!BB5),VLOOKUP(基本信息!$I5,各地政策!$A:$X,23,0)),IF(VLOOKUP(基本信息!$I5,各地政策!$A:$X,24,0)="四舍五入",ROUND(基本信息!AM5*(基本信息!BB5),VLOOKUP(基本信息!$I5,各地政策!$A:$X,23,0)),ROUND(基本信息!AM5*(基本信息!BB5)-IF(VLOOKUP(基本信息!$I5,各地政策!$A:$X,23,0)=0,0.5,IF(VLOOKUP(基本信息!$I5,各地政策!$A:$X,23,0)=1,0.05,0.005)),VLOOKUP(基本信息!$I5,各地政策!$A:$X,23,0)))) -> #N/A | CD5: =AX5+BE5+IFERROR(VLOOKUP($A5,YTD!$A:$CD,82,0),0) -> 0 | CE5: =基本信息!CT5 -> 0 | CF5: ='S-Payroll Report'!X11 -> 0 | CG5: ='S-Payroll Report'!AD11 -> 0 | CH5: ='S-Payroll Report'!AC11 -> 0 | CI5: ='S-Payroll Report'!AA11 -> 450 | CJ5: ='S-Payroll Report'!AF11 -> 30.47 | CK5: =基本信息!EM5+基本信息!EN5+基本信息!EO5 -> 0
